START TIME: Wed May 21 03:37:57 CEST 2025
slurmstepd: error: couldn't chdir to `/workspace': No such file or directory: going to /tmp instead
slurmstepd: error: couldn't chdir to `/workspace': No such file or directory: going to /tmp instead
slurmstepd: error: couldn't chdir to `/workspace': No such file or directory: going to /tmp instead
slurmstepd: error: couldn't chdir to `/workspace': No such file or directory: going to /tmp instead
[rank2]: Traceback (most recent call last):
[rank2]:   File "/iopsstor/scratch/cscs/elyulina/lai-proj/load_model_fsdp.py", line 200, in <module>
[rank2]:     load_model_fsdp(scaling_factor=21, scaling_strategy=scaling_strategy, auto_wrap_policy=auto_wrap_policy)
[rank2]:   File "/iopsstor/scratch/cscs/elyulina/lai-proj/load_model_fsdp.py", line 94, in load_model_fsdp
[rank2]:     with enable_wrap(**fsdp_config):
[rank2]:          ^^^^^^^^^^^^^^^^^^^^^^^^^^
[rank2]:   File "/usr/lib/python3.12/contextlib.py", line 301, in helper
[rank2]:     return _GeneratorContextManager(func, args, kwds)
[rank2]:            ^^^^^^^^^^^^^^^^^^^^^^^^^^^^^^^^^^^^^^^^^^
[rank2]:   File "/usr/lib/python3.12/contextlib.py", line 105, in __init__
[rank2]:     self.gen = func(*args, **kwds)
[rank2]:                ^^^^^^^^^^^^^^^^^^^
[rank2]: TypeError: enable_wrap() missing 1 required keyword-only argument: 'wrapper_cls'
W0521 03:38:26.207000 111080 torch/distributed/elastic/multiprocessing/api.py:897] Sending process 111427 closing signal SIGTERM
W0521 03:38:26.208000 111080 torch/distributed/elastic/multiprocessing/api.py:897] Sending process 111428 closing signal SIGTERM
W0521 03:38:26.209000 111080 torch/distributed/elastic/multiprocessing/api.py:897] Sending process 111430 closing signal SIGTERM
E0521 03:38:26.226000 111080 torch/distributed/elastic/multiprocessing/api.py:869] failed (exitcode: 1) local_rank: 2 (pid: 111429) of binary: /usr/bin/python
Traceback (most recent call last):
  File "<frozen runpy>", line 198, in _run_module_as_main
  File "<frozen runpy>", line 88, in _run_code
  File "/usr/local/lib/python3.12/dist-packages/torch/distributed/run.py", line 922, in <module>
    main()
  File "/usr/local/lib/python3.12/dist-packages/torch/distributed/elastic/multiprocessing/errors/__init__.py", line 355, in wrapper
    return f(*args, **kwargs)
           ^^^^^^^^^^^^^^^^^^
  File "/usr/local/lib/python3.12/dist-packages/torch/distributed/run.py", line 918, in main
    run(args)
  File "/usr/local/lib/python3.12/dist-packages/torch/distributed/run.py", line 909, in run
    elastic_launch(
  File "/usr/local/lib/python3.12/dist-packages/torch/distributed/launcher/api.py", line 138, in __call__
    return launch_agent(self._config, self._entrypoint, list(args))
           ^^^^^^^^^^^^^^^^^^^^^^^^^^^^^^^^^^^^^^^^^^^^^^^^^^^^^^^^
  File "/usr/local/lib/python3.12/dist-packages/torch/distributed/launcher/api.py", line 269, in launch_agent
    raise ChildFailedError(
torch.distributed.elastic.multiprocessing.errors.ChildFailedError: 
============================================================
/iopsstor/scratch/cscs/elyulina/lai-proj/load_model_fsdp.py FAILED
------------------------------------------------------------
Failures:
  <NO_OTHER_FAILURES>
------------------------------------------------------------
Root Cause (first observed failure):
[0]:
  time      : 2025-05-21_03:38:26
  host      : nid006793
  rank      : 2 (local_rank: 2)
  exitcode  : 1 (pid: 111429)
  error_file: <N/A>
  traceback : To enable traceback see: https://pytorch.org/docs/stable/elastic/errors.html
============================================================
W0521 03:38:26.517000 122123 torch/distributed/elastic/multiprocessing/api.py:897] Sending process 122467 closing signal SIGTERM
W0521 03:38:26.518000 122123 torch/distributed/elastic/multiprocessing/api.py:897] Sending process 122468 closing signal SIGTERM
W0521 03:38:26.519000 122123 torch/distributed/elastic/multiprocessing/api.py:897] Sending process 122469 closing signal SIGTERM
W0521 03:38:26.520000 122123 torch/distributed/elastic/multiprocessing/api.py:897] Sending process 122470 closing signal SIGTERM
[W521 03:38:26.281530756 TCPStore.cpp:106] [c10d] sendBytes failed on SocketImpl(fd=3, addr=[nid006859-hsn1]:45970, remote=[nid006793]:29500): Broken pipe
Exception raised from sendBytes at /opt/pytorch/pytorch/torch/csrc/distributed/c10d/Utils.hpp:646 (most recent call first):
frame #0: c10::Error::Error(c10::SourceLocation, std::__cxx11::basic_string<char, std::char_traits<char>, std::allocator<char> >) + 0xd4 (0x40006dd4bdd4 in /usr/local/lib/python3.12/dist-packages/torch/lib/libc10.so)
frame #1: <unknown function> + 0x58a89c0 (0x4000245a89c0 in /usr/local/lib/python3.12/dist-packages/torch/lib/libtorch_cpu.so)
frame #2: <unknown function> + 0x58a8fcc (0x4000245a8fcc in /usr/local/lib/python3.12/dist-packages/torch/lib/libtorch_cpu.so)
frame #3: <unknown function> + 0x58ad124 (0x4000245ad124 in /usr/local/lib/python3.12/dist-packages/torch/lib/libtorch_cpu.so)
frame #4: c10d::TCPStore::doWait(c10::ArrayRef<std::__cxx11::basic_string<char, std::char_traits<char>, std::allocator<char> > >, std::chrono::duration<long, std::ratio<1l, 1000l> >) + 0x148 (0x4000245aec48 in /usr/local/lib/python3.12/dist-packages/torch/lib/libtorch_cpu.so)
frame #5: c10d::TCPStore::doGet(std::__cxx11::basic_string<char, std::char_traits<char>, std::allocator<char> > const&) + 0x2c (0x4000245af10c in /usr/local/lib/python3.12/dist-packages/torch/lib/libtorch_cpu.so)
frame #6: c10d::TCPStore::get(std::__cxx11::basic_string<char, std::char_traits<char>, std::allocator<char> > const&) + 0x9c (0x4000245b061c in /usr/local/lib/python3.12/dist-packages/torch/lib/libtorch_cpu.so)
frame #7: <unknown function> + 0xfd9044 (0x40001ebd9044 in /usr/local/lib/python3.12/dist-packages/torch/lib/libtorch_python.so)
frame #8: <unknown function> + 0x63c060 (0x40001e23c060 in /usr/local/lib/python3.12/dist-packages/torch/lib/libtorch_python.so)
frame #9: /usr/bin/python() [0x503e14]
frame #10: _PyObject_MakeTpCall + 0x78 (0x4c2db8 in /usr/bin/python)
frame #11: /usr/bin/python() [0x4c709c]
frame #12: _PyEval_EvalFrameDefault + 0x3e70 (0x567d34 in /usr/bin/python)
frame #13: _PyObject_Call_Prepend + 0xc4 (0x4c4894 in /usr/bin/python)
frame #14: /usr/bin/python() [0x529450]
frame #15: PyObject_Call + 0xa4 (0x4c52d4 in /usr/bin/python)
frame #16: _PyEval_EvalFrameDefault + 0x3e70 (0x567d34 in /usr/bin/python)
frame #17: PyEval_EvalCode + 0x130 (0x562ab4 in /usr/bin/python)
frame #18: /usr/bin/python() [0x55f968]
frame #19: /usr/bin/python() [0x503c0c]
frame #20: PyObject_Vectorcall + 0x4c (0x4c396c in /usr/bin/python)
frame #21: _PyEval_EvalFrameDefault + 0x8a0 (0x564764 in /usr/bin/python)
frame #22: /usr/bin/python() [0x68bad8]
frame #23: Py_RunMain + 0x1ac (0x68b19c in /usr/bin/python)
frame #24: Py_BytesMain + 0x28 (0x68ae88 in /usr/bin/python)
frame #25: <unknown function> + 0x284c4 (0x40001d0d84c4 in /usr/lib/aarch64-linux-gnu/libc.so.6)
frame #26: __libc_start_main + 0x98 (0x40001d0d8598 in /usr/lib/aarch64-linux-gnu/libc.so.6)
frame #27: _start + 0x30 (0x5f6e30 in /usr/bin/python)

W0521 03:38:26.956000 122123 torch/distributed/elastic/rendezvous/dynamic_rendezvous.py:1284] The node 'nid006859_122123_0' has failed to shutdown the rendezvous 'none' due to an error of type RendezvousConnectionError.
[W521 03:38:26.295570019 TCPStore.cpp:106] [c10d] sendBytes failed on SocketImpl(fd=3, addr=[nid006859-hsn1]:45970, remote=[nid006793]:29500): Broken pipe
Exception raised from sendBytes at /opt/pytorch/pytorch/torch/csrc/distributed/c10d/Utils.hpp:646 (most recent call first):
frame #0: c10::Error::Error(c10::SourceLocation, std::__cxx11::basic_string<char, std::char_traits<char>, std::allocator<char> >) + 0xd4 (0x40006dd4bdd4 in /usr/local/lib/python3.12/dist-packages/torch/lib/libc10.so)
frame #1: <unknown function> + 0x58a89c0 (0x4000245a89c0 in /usr/local/lib/python3.12/dist-packages/torch/lib/libtorch_cpu.so)
frame #2: <unknown function> + 0x58a8fcc (0x4000245a8fcc in /usr/local/lib/python3.12/dist-packages/torch/lib/libtorch_cpu.so)
frame #3: <unknown function> + 0x58ad124 (0x4000245ad124 in /usr/local/lib/python3.12/dist-packages/torch/lib/libtorch_cpu.so)
frame #4: c10d::TCPStore::doWait(c10::ArrayRef<std::__cxx11::basic_string<char, std::char_traits<char>, std::allocator<char> > >, std::chrono::duration<long, std::ratio<1l, 1000l> >) + 0x148 (0x4000245aec48 in /usr/local/lib/python3.12/dist-packages/torch/lib/libtorch_cpu.so)
frame #5: c10d::TCPStore::doGet(std::__cxx11::basic_string<char, std::char_traits<char>, std::allocator<char> > const&) + 0x2c (0x4000245af10c in /usr/local/lib/python3.12/dist-packages/torch/lib/libtorch_cpu.so)
frame #6: c10d::TCPStore::get(std::__cxx11::basic_string<char, std::char_traits<char>, std::allocator<char> > const&) + 0x9c (0x4000245b061c in /usr/local/lib/python3.12/dist-packages/torch/lib/libtorch_cpu.so)
frame #7: <unknown function> + 0xfd9044 (0x40001ebd9044 in /usr/local/lib/python3.12/dist-packages/torch/lib/libtorch_python.so)
frame #8: <unknown function> + 0x63c060 (0x40001e23c060 in /usr/local/lib/python3.12/dist-packages/torch/lib/libtorch_python.so)
frame #9: /usr/bin/python() [0x503e14]
frame #10: _PyObject_MakeTpCall + 0x78 (0x4c2db8 in /usr/bin/python)
frame #11: /usr/bin/python() [0x4c709c]
frame #12: _PyEval_EvalFrameDefault + 0x3e70 (0x567d34 in /usr/bin/python)
frame #13: _PyObject_Call_Prepend + 0xc4 (0x4c4894 in /usr/bin/python)
frame #14: /usr/bin/python() [0x529450]
frame #15: PyObject_Call + 0xa4 (0x4c52d4 in /usr/bin/python)
frame #16: _PyEval_EvalFrameDefault + 0x3e70 (0x567d34 in /usr/bin/python)
frame #17: PyEval_EvalCode + 0x130 (0x562ab4 in /usr/bin/python)
frame #18: /usr/bin/python() [0x55f968]
frame #19: /usr/bin/python() [0x503c0c]
frame #20: PyObject_Vectorcall + 0x4c (0x4c396c in /usr/bin/python)
frame #21: _PyEval_EvalFrameDefault + 0x8a0 (0x564764 in /usr/bin/python)
frame #22: /usr/bin/python() [0x68bad8]
frame #23: Py_RunMain + 0x1ac (0x68b19c in /usr/bin/python)
frame #24: Py_BytesMain + 0x28 (0x68ae88 in /usr/bin/python)
frame #25: <unknown function> + 0x284c4 (0x40001d0d84c4 in /usr/lib/aarch64-linux-gnu/libc.so.6)
frame #26: __libc_start_main + 0x98 (0x40001d0d8598 in /usr/lib/aarch64-linux-gnu/libc.so.6)
frame #27: _start + 0x30 (0x5f6e30 in /usr/bin/python)

W0521 03:38:26.969000 122123 torch/distributed/elastic/rendezvous/dynamic_rendezvous.py:1284] The node 'nid006859_122123_0' has failed to shutdown the rendezvous 'none' due to an error of type RendezvousConnectionError.
Traceback (most recent call last):
  File "/usr/local/lib/python3.12/dist-packages/torch/distributed/elastic/rendezvous/c10d_rendezvous_backend.py", line 117, in _call_store
    return getattr(self._store, store_op)(*args, **kwargs)
           ^^^^^^^^^^^^^^^^^^^^^^^^^^^^^^^^^^^^^^^^^^^^^^^
torch.distributed.DistNetworkError: failed to recv, got 0 bytes

The above exception was the direct cause of the following exception:

Traceback (most recent call last):
  File "<frozen runpy>", line 198, in _run_module_as_main
  File "<frozen runpy>", line 88, in _run_code
  File "/usr/local/lib/python3.12/dist-packages/torch/distributed/run.py", line 922, in <module>
    main()
  File "/usr/local/lib/python3.12/dist-packages/torch/distributed/elastic/multiprocessing/errors/__init__.py", line 355, in wrapper
    return f(*args, **kwargs)
           ^^^^^^^^^^^^^^^^^^
  File "/usr/local/lib/python3.12/dist-packages/torch/distributed/run.py", line 918, in main
    run(args)
  File "/usr/local/lib/python3.12/dist-packages/torch/distributed/run.py", line 909, in run
    elastic_launch(
  File "/usr/local/lib/python3.12/dist-packages/torch/distributed/launcher/api.py", line 138, in __call__
    return launch_agent(self._config, self._entrypoint, list(args))
           ^^^^^^^^^^^^^^^^^^^^^^^^^^^^^^^^^^^^^^^^^^^^^^^^^^^^^^^^
  File "/usr/local/lib/python3.12/dist-packages/torch/distributed/launcher/api.py", line 260, in launch_agent
    result = agent.run()
             ^^^^^^^^^^^
  File "/usr/local/lib/python3.12/dist-packages/torch/distributed/elastic/metrics/api.py", line 137, in wrapper
    result = f(*args, **kwargs)
             ^^^^^^^^^^^^^^^^^^
  File "/usr/local/lib/python3.12/dist-packages/torch/distributed/elastic/agent/server/api.py", line 711, in run
    result = self._invoke_run(role)
             ^^^^^^^^^^^^^^^^^^^^^^
  File "/usr/local/lib/python3.12/dist-packages/torch/distributed/elastic/agent/server/api.py", line 906, in _invoke_run
    num_nodes_waiting = rdzv_handler.num_nodes_waiting()
                        ^^^^^^^^^^^^^^^^^^^^^^^^^^^^^^^^
  File "/usr/local/lib/python3.12/dist-packages/torch/distributed/elastic/rendezvous/dynamic_rendezvous.py", line 1255, in num_nodes_waiting
    self._state_holder.sync()
  File "/usr/local/lib/python3.12/dist-packages/torch/distributed/elastic/rendezvous/dynamic_rendezvous.py", line 437, in sync
    get_response = self._backend.get_state()
                   ^^^^^^^^^^^^^^^^^^^^^^^^^
  File "/usr/local/lib/python3.12/dist-packages/torch/distributed/elastic/rendezvous/c10d_rendezvous_backend.py", line 75, in get_state
    base64_state: bytes = self._call_store("get", self._key)
                          ^^^^^^^^^^^^^^^^^^^^^^^^^^^^^^^^^^
  File "/usr/local/lib/python3.12/dist-packages/torch/distributed/elastic/rendezvous/c10d_rendezvous_backend.py", line 119, in _call_store
    raise RendezvousConnectionError(
torch.distributed.elastic.rendezvous.api.RendezvousConnectionError: The connection to the C10d store has failed. See inner exception for details.
srun: error: nid006793: task 0: Exited with exit code 1
srun: Terminating StepId=454279.0
srun: error: nid006859: task 1: Exited with exit code 1
