START TIME: Wed May 21 04:28:13 CEST 2025
slurmstepd: error: couldn't chdir to `/workspace': No such file or directory: going to /tmp instead
slurmstepd: error: couldn't chdir to `/workspace': No such file or directory: going to /tmp instead
slurmstepd: error: couldn't chdir to `/workspace': No such file or directory: going to /tmp instead
slurmstepd: error: couldn't chdir to `/workspace': No such file or directory: going to /tmp instead
2025-05-21 04:28:46,530 - root - INFO - Loading a model with scale=21, scaling_strategy=ScalingStrategy.ALL, config:
TransformerModelArgs(dim=5376, n_layers=168, n_heads=168, n_kv_heads=8, multiple_of=256, ffn_dim_multiplier=1.3, norm_eps=1e-05, rope_theta=500000, norm_type='rmsnorm', seq_len=4096, vocab_size=131072)
Traceback (most recent call last):
  File "/iopsstor/scratch/cscs/elyulina/lai-proj/load_model_fsdp.py", line 208, in <module>
2025-05-21 04:28:46,532 - root - INFO - Loading a model with scale=21, scaling_strategy=ScalingStrategy.ALL, config:
TransformerModelArgs(dim=5376, n_layers=168, n_heads=168, n_kv_heads=8, multiple_of=256, ffn_dim_multiplier=1.3, norm_eps=1e-05, rope_theta=500000, norm_type='rmsnorm', seq_len=4096, vocab_size=131072)
Traceback (most recent call last):
  File "/iopsstor/scratch/cscs/elyulina/lai-proj/load_model_fsdp.py", line 208, in <module>
2025-05-21 04:28:46,532 - root - INFO - Loading a model with scale=21, scaling_strategy=ScalingStrategy.ALL, config:
TransformerModelArgs(dim=5376, n_layers=168, n_heads=168, n_kv_heads=8, multiple_of=256, ffn_dim_multiplier=1.3, norm_eps=1e-05, rope_theta=500000, norm_type='rmsnorm', seq_len=4096, vocab_size=131072)
Traceback (most recent call last):
  File "/iopsstor/scratch/cscs/elyulina/lai-proj/load_model_fsdp.py", line 208, in <module>
        load_model_fsdp(scaling_factor=21, scaling_strategy=scaling_strategy)load_model_fsdp(scaling_factor=21, scaling_strategy=scaling_strategy)

    load_model_fsdp(scaling_factor=21, scaling_strategy=scaling_strategy)
  File "/iopsstor/scratch/cscs/elyulina/lai-proj/load_model_fsdp.py", line 70, in load_model_fsdp
  File "/iopsstor/scratch/cscs/elyulina/lai-proj/load_model_fsdp.py", line 70, in load_model_fsdp
  File "/iopsstor/scratch/cscs/elyulina/lai-proj/load_model_fsdp.py", line 70, in load_model_fsdp
    with set_default_dtype(model_dtype):
        with set_default_dtype(model_dtype):with set_default_dtype(model_dtype): 

                                                              ^  ^  ^  ^  ^  ^  ^  ^^ ^^ ^^ ^^ 
^^^^^^UnboundLocalError^^^^^: ^^^cannot access local variable 'model_dtype' where it is not associated with a value^
^^^

UnboundLocalError: cannot access local variable 'model_dtype' where it is not associated with a value
UnboundLocalError: cannot access local variable 'model_dtype' where it is not associated with a value
2025-05-21 04:28:46,634 - root - INFO - Loading a model with scale=21, scaling_strategy=ScalingStrategy.ALL, config:
TransformerModelArgs(dim=5376, n_layers=168, n_heads=168, n_kv_heads=8, multiple_of=256, ffn_dim_multiplier=1.3, norm_eps=1e-05, rope_theta=500000, norm_type='rmsnorm', seq_len=4096, vocab_size=131072)
Traceback (most recent call last):
  File "/iopsstor/scratch/cscs/elyulina/lai-proj/load_model_fsdp.py", line 208, in <module>
    load_model_fsdp(scaling_factor=21, scaling_strategy=scaling_strategy)
  File "/iopsstor/scratch/cscs/elyulina/lai-proj/load_model_fsdp.py", line 70, in load_model_fsdp
    with set_default_dtype(model_dtype):
                           ^^^^^^^^^^^
UnboundLocalError: cannot access local variable 'model_dtype' where it is not associated with a value
2025-05-21 04:28:46,660 - root - INFO - Loading a model with scale=21, scaling_strategy=ScalingStrategy.ALL, config:
TransformerModelArgs(dim=5376, n_layers=168, n_heads=168, n_kv_heads=8, multiple_of=256, ffn_dim_multiplier=1.3, norm_eps=1e-05, rope_theta=500000, norm_type='rmsnorm', seq_len=4096, vocab_size=131072)
2025-05-21 04:28:46,660 - root - INFO - Loading a model with scale=21, scaling_strategy=ScalingStrategy.ALL, config:
TransformerModelArgs(dim=5376, n_layers=168, n_heads=168, n_kv_heads=8, multiple_of=256, ffn_dim_multiplier=1.3, norm_eps=1e-05, rope_theta=500000, norm_type='rmsnorm', seq_len=4096, vocab_size=131072)
Traceback (most recent call last):
Traceback (most recent call last):
  File "/iopsstor/scratch/cscs/elyulina/lai-proj/load_model_fsdp.py", line 208, in <module>
  File "/iopsstor/scratch/cscs/elyulina/lai-proj/load_model_fsdp.py", line 208, in <module>
2025-05-21 04:28:46,662 - root - INFO - Loading a model with scale=21, scaling_strategy=ScalingStrategy.ALL, config:
TransformerModelArgs(dim=5376, n_layers=168, n_heads=168, n_kv_heads=8, multiple_of=256, ffn_dim_multiplier=1.3, norm_eps=1e-05, rope_theta=500000, norm_type='rmsnorm', seq_len=4096, vocab_size=131072)
    load_model_fsdp(scaling_factor=21, scaling_strategy=scaling_strategy)    
load_model_fsdp(scaling_factor=21, scaling_strategy=scaling_strategy)
Traceback (most recent call last):
  File "/iopsstor/scratch/cscs/elyulina/lai-proj/load_model_fsdp.py", line 208, in <module>
  File "/iopsstor/scratch/cscs/elyulina/lai-proj/load_model_fsdp.py", line 70, in load_model_fsdp
  File "/iopsstor/scratch/cscs/elyulina/lai-proj/load_model_fsdp.py", line 70, in load_model_fsdp
    with set_default_dtype(model_dtype):
    with set_default_dtype(model_dtype):
                            load_model_fsdp(scaling_factor=21, scaling_strategy=scaling_strategy)  
              File "/iopsstor/scratch/cscs/elyulina/lai-proj/load_model_fsdp.py", line 70, in load_model_fsdp
            ^^ ^ ^ ^ ^^^^^^^^^^^^
    UnboundLocalError^^with set_default_dtype(model_dtype):^
: ^cannot access local variable 'model_dtype' where it is not associated with a value^

 UnboundLocalError :  cannot access local variable 'model_dtype' where it is not associated with a value 
                       ^^^^^^^^^^^
UnboundLocalError: cannot access local variable 'model_dtype' where it is not associated with a value
2025-05-21 04:28:46,663 - root - INFO - Loading a model with scale=21, scaling_strategy=ScalingStrategy.ALL, config:
TransformerModelArgs(dim=5376, n_layers=168, n_heads=168, n_kv_heads=8, multiple_of=256, ffn_dim_multiplier=1.3, norm_eps=1e-05, rope_theta=500000, norm_type='rmsnorm', seq_len=4096, vocab_size=131072)
Traceback (most recent call last):
  File "/iopsstor/scratch/cscs/elyulina/lai-proj/load_model_fsdp.py", line 208, in <module>
    load_model_fsdp(scaling_factor=21, scaling_strategy=scaling_strategy)
  File "/iopsstor/scratch/cscs/elyulina/lai-proj/load_model_fsdp.py", line 70, in load_model_fsdp
    with set_default_dtype(model_dtype):
                           ^^^^^^^^^^^
UnboundLocalError: cannot access local variable 'model_dtype' where it is not associated with a value
E0521 04:28:47.284000 107226 torch/distributed/elastic/multiprocessing/api.py:869] failed (exitcode: 1) local_rank: 0 (pid: 107582) of binary: /usr/bin/python
Traceback (most recent call last):
  File "<frozen runpy>", line 198, in _run_module_as_main
  File "<frozen runpy>", line 88, in _run_code
  File "/usr/local/lib/python3.12/dist-packages/torch/distributed/run.py", line 922, in <module>
    main()
  File "/usr/local/lib/python3.12/dist-packages/torch/distributed/elastic/multiprocessing/errors/__init__.py", line 355, in wrapper
    return f(*args, **kwargs)
           ^^^^^^^^^^^^^^^^^^
  File "/usr/local/lib/python3.12/dist-packages/torch/distributed/run.py", line 918, in main
    run(args)
  File "/usr/local/lib/python3.12/dist-packages/torch/distributed/run.py", line 909, in run
    elastic_launch(
  File "/usr/local/lib/python3.12/dist-packages/torch/distributed/launcher/api.py", line 138, in __call__
    return launch_agent(self._config, self._entrypoint, list(args))
           ^^^^^^^^^^^^^^^^^^^^^^^^^^^^^^^^^^^^^^^^^^^^^^^^^^^^^^^^
  File "/usr/local/lib/python3.12/dist-packages/torch/distributed/launcher/api.py", line 269, in launch_agent
    raise ChildFailedError(
torch.distributed.elastic.multiprocessing.errors.ChildFailedError: 
============================================================
/iopsstor/scratch/cscs/elyulina/lai-proj/load_model_fsdp.py FAILED
------------------------------------------------------------
Failures:
[1]:
  time      : 2025-05-21_04:28:47
  host      : nid006833
  rank      : 5 (local_rank: 1)
  exitcode  : 1 (pid: 107583)
  error_file: <N/A>
  traceback : To enable traceback see: https://pytorch.org/docs/stable/elastic/errors.html
[2]:
  time      : 2025-05-21_04:28:47
  host      : nid006833
  rank      : 6 (local_rank: 2)
  exitcode  : 1 (pid: 107584)
  error_file: <N/A>
  traceback : To enable traceback see: https://pytorch.org/docs/stable/elastic/errors.html
[3]:
  time      : 2025-05-21_04:28:47
  host      : nid006833
  rank      : 7 (local_rank: 3)
  exitcode  : 1 (pid: 107585)
  error_file: <N/A>
  traceback : To enable traceback see: https://pytorch.org/docs/stable/elastic/errors.html
------------------------------------------------------------
Root Cause (first observed failure):
[0]:
  time      : 2025-05-21_04:28:47
  host      : nid006833
  rank      : 4 (local_rank: 0)
  exitcode  : 1 (pid: 107582)
  error_file: <N/A>
  traceback : To enable traceback see: https://pytorch.org/docs/stable/elastic/errors.html
============================================================
E0521 04:28:47.380000 130494 torch/distributed/elastic/multiprocessing/api.py:869] failed (exitcode: 1) local_rank: 0 (pid: 130858) of binary: /usr/bin/python
Traceback (most recent call last):
  File "<frozen runpy>", line 198, in _run_module_as_main
  File "<frozen runpy>", line 88, in _run_code
  File "/usr/local/lib/python3.12/dist-packages/torch/distributed/run.py", line 922, in <module>
    main()
  File "/usr/local/lib/python3.12/dist-packages/torch/distributed/elastic/multiprocessing/errors/__init__.py", line 355, in wrapper
    return f(*args, **kwargs)
           ^^^^^^^^^^^^^^^^^^
  File "/usr/local/lib/python3.12/dist-packages/torch/distributed/run.py", line 918, in main
    run(args)
  File "/usr/local/lib/python3.12/dist-packages/torch/distributed/run.py", line 909, in run
    elastic_launch(
  File "/usr/local/lib/python3.12/dist-packages/torch/distributed/launcher/api.py", line 138, in __call__
    return launch_agent(self._config, self._entrypoint, list(args))
           ^^^^^^^^^^^^^^^^^^^^^^^^^^^^^^^^^^^^^^^^^^^^^^^^^^^^^^^^
  File "/usr/local/lib/python3.12/dist-packages/torch/distributed/launcher/api.py", line 269, in launch_agent
    raise ChildFailedError(
torch.distributed.elastic.multiprocessing.errors.ChildFailedError: 
============================================================
/iopsstor/scratch/cscs/elyulina/lai-proj/load_model_fsdp.py FAILED
------------------------------------------------------------
Failures:
[1]:
  time      : 2025-05-21_04:28:47
  host      : nid006793
  rank      : 1 (local_rank: 1)
  exitcode  : 1 (pid: 130859)
  error_file: <N/A>
  traceback : To enable traceback see: https://pytorch.org/docs/stable/elastic/errors.html
[2]:
  time      : 2025-05-21_04:28:47
  host      : nid006793
  rank      : 2 (local_rank: 2)
  exitcode  : 1 (pid: 130860)
  error_file: <N/A>
  traceback : To enable traceback see: https://pytorch.org/docs/stable/elastic/errors.html
[3]:
  time      : 2025-05-21_04:28:47
  host      : nid006793
  rank      : 3 (local_rank: 3)
  exitcode  : 1 (pid: 130861)
  error_file: <N/A>
  traceback : To enable traceback see: https://pytorch.org/docs/stable/elastic/errors.html
------------------------------------------------------------
Root Cause (first observed failure):
[0]:
  time      : 2025-05-21_04:28:47
  host      : nid006793
  rank      : 0 (local_rank: 0)
  exitcode  : 1 (pid: 130858)
  error_file: <N/A>
  traceback : To enable traceback see: https://pytorch.org/docs/stable/elastic/errors.html
============================================================
srun: error: nid006833: task 1: Exited with exit code 1
srun: Terminating StepId=454296.0
srun: error: nid006793: task 0: Exited with exit code 1
