START TIME: Wed May 21 23:31:33 CEST 2025
slurmstepd: error: couldn't chdir to `/workspace': No such file or directory: going to /tmp instead
slurmstepd: error: couldn't chdir to `/workspace': No such file or directory: going to /tmp instead
slurmstepd: error: couldn't chdir to `/workspace': No such file or directory: going to /tmp instead
2025-05-21 23:31:54,692 - root - INFO - Loading a model with scale=19, scaling_strategy=ScalingStrategy.ALL, config:
TransformerModelArgs(dim=4864, n_layers=152, n_heads=152, n_kv_heads=8, multiple_of=256, ffn_dim_multiplier=1.3, norm_eps=1e-05, rope_theta=500000, norm_type='rmsnorm', seq_len=4096, vocab_size=131072)
2025-05-21 23:31:54,693 - root - INFO - Loading a model with scale=19, scaling_strategy=ScalingStrategy.ALL, config:
TransformerModelArgs(dim=4864, n_layers=152, n_heads=152, n_kv_heads=8, multiple_of=256, ffn_dim_multiplier=1.3, norm_eps=1e-05, rope_theta=500000, norm_type='rmsnorm', seq_len=4096, vocab_size=131072)
2025-05-21 23:31:54,694 - root - INFO - Loading a model with scale=19, scaling_strategy=ScalingStrategy.ALL, config:
TransformerModelArgs(dim=4864, n_layers=152, n_heads=152, n_kv_heads=8, multiple_of=256, ffn_dim_multiplier=1.3, norm_eps=1e-05, rope_theta=500000, norm_type='rmsnorm', seq_len=4096, vocab_size=131072)
2025-05-21 23:31:54,696 - root - INFO - Loading a model with scale=19, scaling_strategy=ScalingStrategy.ALL, config:
TransformerModelArgs(dim=4864, n_layers=152, n_heads=152, n_kv_heads=8, multiple_of=256, ffn_dim_multiplier=1.3, norm_eps=1e-05, rope_theta=500000, norm_type='rmsnorm', seq_len=4096, vocab_size=131072)
2025-05-21 23:34:49,516 - root - INFO - Total model parameters: 46,322,328,320
2025-05-21 23:34:51,164 - root - INFO - Total model parameters: 46,322,328,320
2025-05-21 23:34:51,268 - root - INFO - Total model parameters: 46,322,328,320
2025-05-21 23:34:53,853 - root - INFO - Total model parameters: 46,322,328,320
2025-05-21 23:34:55,502 - root - INFO - [rank 0]Took 3 min 1 sec
2025-05-21 23:34:55,502 - root - INFO - [rank 0]


[W521 23:35:05.047353549 TCPStore.cpp:106] [c10d] sendBytes failed on SocketImpl(fd=3, addr=[nid007019]:53178, remote=[nid007019]:29500): Broken pipe
Exception raised from sendBytes at /opt/pytorch/pytorch/torch/csrc/distributed/c10d/Utils.hpp:646 (most recent call first):
frame #0: c10::Error::Error(c10::SourceLocation, std::__cxx11::basic_string<char, std::char_traits<char>, std::allocator<char> >) + 0xd4 (0x400070d6bdd4 in /usr/local/lib/python3.12/dist-packages/torch/lib/libc10.so)
frame #1: <unknown function> + 0x58a89c0 (0x4000275c89c0 in /usr/local/lib/python3.12/dist-packages/torch/lib/libtorch_cpu.so)
frame #2: <unknown function> + 0x58a8fcc (0x4000275c8fcc in /usr/local/lib/python3.12/dist-packages/torch/lib/libtorch_cpu.so)
frame #3: <unknown function> + 0x58ad124 (0x4000275cd124 in /usr/local/lib/python3.12/dist-packages/torch/lib/libtorch_cpu.so)
frame #4: c10d::TCPStore::doWait(c10::ArrayRef<std::__cxx11::basic_string<char, std::char_traits<char>, std::allocator<char> > >, std::chrono::duration<long, std::ratio<1l, 1000l> >) + 0x148 (0x4000275cec48 in /usr/local/lib/python3.12/dist-packages/torch/lib/libtorch_cpu.so)
frame #5: c10d::TCPStore::doGet(std::__cxx11::basic_string<char, std::char_traits<char>, std::allocator<char> > const&) + 0x2c (0x4000275cf10c in /usr/local/lib/python3.12/dist-packages/torch/lib/libtorch_cpu.so)
frame #6: c10d::TCPStore::get(std::__cxx11::basic_string<char, std::char_traits<char>, std::allocator<char> > const&) + 0x9c (0x4000275d061c in /usr/local/lib/python3.12/dist-packages/torch/lib/libtorch_cpu.so)
frame #7: <unknown function> + 0xfd9044 (0x400021bf9044 in /usr/local/lib/python3.12/dist-packages/torch/lib/libtorch_python.so)
frame #8: <unknown function> + 0x63c060 (0x40002125c060 in /usr/local/lib/python3.12/dist-packages/torch/lib/libtorch_python.so)
frame #9: /usr/bin/python() [0x503e14]
frame #10: _PyObject_MakeTpCall + 0x78 (0x4c2db8 in /usr/bin/python)
frame #11: /usr/bin/python() [0x4c709c]
frame #12: _PyEval_EvalFrameDefault + 0x3e70 (0x567d34 in /usr/bin/python)
frame #13: _PyObject_Call_Prepend + 0xc4 (0x4c4894 in /usr/bin/python)
frame #14: /usr/bin/python() [0x529450]
frame #15: PyObject_Call + 0xa4 (0x4c52d4 in /usr/bin/python)
frame #16: _PyEval_EvalFrameDefault + 0x3e70 (0x567d34 in /usr/bin/python)
frame #17: PyEval_EvalCode + 0x130 (0x562ab4 in /usr/bin/python)
frame #18: /usr/bin/python() [0x55f968]
frame #19: /usr/bin/python() [0x503c0c]
frame #20: PyObject_Vectorcall + 0x4c (0x4c396c in /usr/bin/python)
frame #21: _PyEval_EvalFrameDefault + 0x8a0 (0x564764 in /usr/bin/python)
frame #22: /usr/bin/python() [0x68bad8]
frame #23: Py_RunMain + 0x1ac (0x68b19c in /usr/bin/python)
frame #24: Py_BytesMain + 0x28 (0x68ae88 in /usr/bin/python)
frame #25: <unknown function> + 0x284c4 (0x4000200f84c4 in /usr/lib/aarch64-linux-gnu/libc.so.6)
frame #26: __libc_start_main + 0x98 (0x4000200f8598 in /usr/lib/aarch64-linux-gnu/libc.so.6)
frame #27: _start + 0x30 (0x5f6e30 in /usr/bin/python)

W0521 23:35:05.371000 28543 torch/distributed/elastic/rendezvous/dynamic_rendezvous.py:1284] The node 'nid007019_28543_0' has failed to shutdown the rendezvous 'none' due to an error of type RendezvousConnectionError.
[W521 23:35:05.059814776 TCPStore.cpp:106] [c10d] sendBytes failed on SocketImpl(fd=3, addr=[nid007019]:53178, remote=[nid007019]:29500): Broken pipe
Exception raised from sendBytes at /opt/pytorch/pytorch/torch/csrc/distributed/c10d/Utils.hpp:646 (most recent call first):
frame #0: c10::Error::Error(c10::SourceLocation, std::__cxx11::basic_string<char, std::char_traits<char>, std::allocator<char> >) + 0xd4 (0x400070d6bdd4 in /usr/local/lib/python3.12/dist-packages/torch/lib/libc10.so)
frame #1: <unknown function> + 0x58a89c0 (0x4000275c89c0 in /usr/local/lib/python3.12/dist-packages/torch/lib/libtorch_cpu.so)
frame #2: <unknown function> + 0x58a8fcc (0x4000275c8fcc in /usr/local/lib/python3.12/dist-packages/torch/lib/libtorch_cpu.so)
frame #3: <unknown function> + 0x58ad124 (0x4000275cd124 in /usr/local/lib/python3.12/dist-packages/torch/lib/libtorch_cpu.so)
frame #4: c10d::TCPStore::doWait(c10::ArrayRef<std::__cxx11::basic_string<char, std::char_traits<char>, std::allocator<char> > >, std::chrono::duration<long, std::ratio<1l, 1000l> >) + 0x148 (0x4000275cec48 in /usr/local/lib/python3.12/dist-packages/torch/lib/libtorch_cpu.so)
frame #5: c10d::TCPStore::doGet(std::__cxx11::basic_string<char, std::char_traits<char>, std::allocator<char> > const&) + 0x2c (0x4000275cf10c in /usr/local/lib/python3.12/dist-packages/torch/lib/libtorch_cpu.so)
frame #6: c10d::TCPStore::get(std::__cxx11::basic_string<char, std::char_traits<char>, std::allocator<char> > const&) + 0x9c (0x4000275d061c in /usr/local/lib/python3.12/dist-packages/torch/lib/libtorch_cpu.so)
frame #7: <unknown function> + 0xfd9044 (0x400021bf9044 in /usr/local/lib/python3.12/dist-packages/torch/lib/libtorch_python.so)
frame #8: <unknown function> + 0x63c060 (0x40002125c060 in /usr/local/lib/python3.12/dist-packages/torch/lib/libtorch_python.so)
frame #9: /usr/bin/python() [0x503e14]
frame #10: _PyObject_MakeTpCall + 0x78 (0x4c2db8 in /usr/bin/python)
frame #11: /usr/bin/python() [0x4c709c]
frame #12: _PyEval_EvalFrameDefault + 0x3e70 (0x567d34 in /usr/bin/python)
frame #13: _PyObject_Call_Prepend + 0xc4 (0x4c4894 in /usr/bin/python)
frame #14: /usr/bin/python() [0x529450]
frame #15: PyObject_Call + 0xa4 (0x4c52d4 in /usr/bin/python)
frame #16: _PyEval_EvalFrameDefault + 0x3e70 (0x567d34 in /usr/bin/python)
frame #17: PyEval_EvalCode + 0x130 (0x562ab4 in /usr/bin/python)
frame #18: /usr/bin/python() [0x55f968]
frame #19: /usr/bin/python() [0x503c0c]
frame #20: PyObject_Vectorcall + 0x4c (0x4c396c in /usr/bin/python)
frame #21: _PyEval_EvalFrameDefault + 0x8a0 (0x564764 in /usr/bin/python)
frame #22: /usr/bin/python() [0x68bad8]
frame #23: Py_RunMain + 0x1ac (0x68b19c in /usr/bin/python)
frame #24: Py_BytesMain + 0x28 (0x68ae88 in /usr/bin/python)
frame #25: <unknown function> + 0x284c4 (0x4000200f84c4 in /usr/lib/aarch64-linux-gnu/libc.so.6)
frame #26: __libc_start_main + 0x98 (0x4000200f8598 in /usr/lib/aarch64-linux-gnu/libc.so.6)
frame #27: _start + 0x30 (0x5f6e30 in /usr/bin/python)

W0521 23:35:05.383000 28543 torch/distributed/elastic/rendezvous/dynamic_rendezvous.py:1284] The node 'nid007019_28543_0' has failed to shutdown the rendezvous 'none' due to an error of type RendezvousConnectionError.
Traceback (most recent call last):
  File "/usr/local/lib/python3.12/dist-packages/torch/distributed/elastic/rendezvous/c10d_rendezvous_backend.py", line 117, in _call_store
    return getattr(self._store, store_op)(*args, **kwargs)
           ^^^^^^^^^^^^^^^^^^^^^^^^^^^^^^^^^^^^^^^^^^^^^^^
torch.distributed.DistNetworkError: failed to recv, got 0 bytes

The above exception was the direct cause of the following exception:

Traceback (most recent call last):
  File "<frozen runpy>", line 198, in _run_module_as_main
  File "<frozen runpy>", line 88, in _run_code
  File "/usr/local/lib/python3.12/dist-packages/torch/distributed/run.py", line 922, in <module>
    main()
  File "/usr/local/lib/python3.12/dist-packages/torch/distributed/elastic/multiprocessing/errors/__init__.py", line 355, in wrapper
    return f(*args, **kwargs)
           ^^^^^^^^^^^^^^^^^^
  File "/usr/local/lib/python3.12/dist-packages/torch/distributed/run.py", line 918, in main
    run(args)
  File "/usr/local/lib/python3.12/dist-packages/torch/distributed/run.py", line 909, in run
    elastic_launch(
  File "/usr/local/lib/python3.12/dist-packages/torch/distributed/launcher/api.py", line 138, in __call__
    return launch_agent(self._config, self._entrypoint, list(args))
           ^^^^^^^^^^^^^^^^^^^^^^^^^^^^^^^^^^^^^^^^^^^^^^^^^^^^^^^^
  File "/usr/local/lib/python3.12/dist-packages/torch/distributed/launcher/api.py", line 260, in launch_agent
    result = agent.run()
             ^^^^^^^^^^^
  File "/usr/local/lib/python3.12/dist-packages/torch/distributed/elastic/metrics/api.py", line 137, in wrapper
    result = f(*args, **kwargs)
             ^^^^^^^^^^^^^^^^^^
  File "/usr/local/lib/python3.12/dist-packages/torch/distributed/elastic/agent/server/api.py", line 711, in run
    result = self._invoke_run(role)
             ^^^^^^^^^^^^^^^^^^^^^^
  File "/usr/local/lib/python3.12/dist-packages/torch/distributed/elastic/agent/server/api.py", line 864, in _invoke_run
    self._initialize_workers(self._worker_group)
  File "/usr/local/lib/python3.12/dist-packages/torch/distributed/elastic/metrics/api.py", line 137, in wrapper
    result = f(*args, **kwargs)
             ^^^^^^^^^^^^^^^^^^
  File "/usr/local/lib/python3.12/dist-packages/torch/distributed/elastic/agent/server/api.py", line 683, in _initialize_workers
    self._rendezvous(worker_group)
  File "/usr/local/lib/python3.12/dist-packages/torch/distributed/elastic/metrics/api.py", line 137, in wrapper
    result = f(*args, **kwargs)
             ^^^^^^^^^^^^^^^^^^
  File "/usr/local/lib/python3.12/dist-packages/torch/distributed/elastic/agent/server/api.py", line 500, in _rendezvous
    rdzv_info = spec.rdzv_handler.next_rendezvous()
                ^^^^^^^^^^^^^^^^^^^^^^^^^^^^^^^^^^^
  File "/usr/local/lib/python3.12/dist-packages/torch/distributed/elastic/rendezvous/dynamic_rendezvous.py", line 1162, in next_rendezvous
    self._op_executor.run(join_op, deadline, self._get_deadline)
  File "/usr/local/lib/python3.12/dist-packages/torch/distributed/elastic/rendezvous/dynamic_rendezvous.py", line 648, in run
    has_set = self._state_holder.sync()
              ^^^^^^^^^^^^^^^^^^^^^^^^^
  File "/usr/local/lib/python3.12/dist-packages/torch/distributed/elastic/rendezvous/dynamic_rendezvous.py", line 437, in sync
    get_response = self._backend.get_state()
                   ^^^^^^^^^^^^^^^^^^^^^^^^^
  File "/usr/local/lib/python3.12/dist-packages/torch/distributed/elastic/rendezvous/c10d_rendezvous_backend.py", line 75, in get_state
    base64_state: bytes = self._call_store("get", self._key)
                          ^^^^^^^^^^^^^^^^^^^^^^^^^^^^^^^^^^
  File "/usr/local/lib/python3.12/dist-packages/torch/distributed/elastic/rendezvous/c10d_rendezvous_backend.py", line 119, in _call_store
    raise RendezvousConnectionError(
torch.distributed.elastic.rendezvous.api.RendezvousConnectionError: The connection to the C10d store has failed. See inner exception for details.
srun: error: nid007019: task 1: Exited with exit code 1
srun: Terminating StepId=456192.0
