START TIME: Sun May 18 16:14:28 CEST 2025
slurmstepd: error: couldn't chdir to `/workspace': No such file or directory: going to /tmp instead
slurmstepd: error: couldn't chdir to `/workspace': No such file or directory: going to /tmp instead
slurmstepd: error: couldn't chdir to `/workspace': No such file or directory: going to /tmp instead
slurmstepd: error: couldn't chdir to `/workspace': No such file or directory: going to /tmp instead
slurmstepd: error: couldn't chdir to `/workspace': No such file or directory: going to /tmp instead
2025-05-18 16:14:49,750 - root - INFO - Experiment args: Namespace(dataset='/capstor/store/cscs/ethz/large-sc/datasets/train_data.parquet', tokenizer_name_or_path='unsloth/Mistral-Nemo-Base-2407-bnb-4bit', sequence_length=4096, batch_size=1, fused_optimizer=False, learning_rate=5e-05, lr_warmup_steps=100, training_steps=10, logging_frequency=5, profile=False, profile_step_start=10, profile_step_end=12, grad_max_norm=1, model_dtype='bf16', compile=False, scale=1, set_seed=None)
2025-05-18 16:14:55,201 - root - INFO - [rank 0] world size: 4
2025-05-18 16:14:55,201 - root - INFO - Setting up DataLoaders...
2025-05-18 16:15:02,764 - root - INFO - Setting up Model...
Total params: 8053329920
Total params: 8053329920
2025-05-18 16:15:36,467 - root - INFO - [rank 1] model is now: FullyShardedDataParallel
2025-05-18 16:15:36,467 - root - INFO - [rank 3] model is now: FullyShardedDataParallel
2025-05-18 16:15:36,467 - root - INFO - [rank 3] local params: 2013332480
2025-05-18 16:15:36,467 - root - INFO - [rank 1] local params: 2013332480
Total params: 8053329920
2025-05-18 16:15:36,685 - root - INFO - [rank 2] model is now: FullyShardedDataParallel
2025-05-18 16:15:36,686 - root - INFO - [rank 2] local params: 2013332480
Total params: 8053329920
2025-05-18 16:15:38,005 - root - INFO - [rank 0] model is now: FullyShardedDataParallel
2025-05-18 16:15:38,006 - root - INFO - [rank 0] local params: 2013332480
2025-05-18 16:15:38,007 - root - INFO - Starting training!
2025-05-18 16:15:47,011 - root - INFO - Step: 1 | Loss: 11.89 | Tokens per second: 455.33 | Training tokens per second (%): 19.38 | MFU (%): 0.85 | TFLOPs: 8.43
2025-05-18 16:15:49,251 - root - INFO - Step: 5 | Loss: 11.95 | Tokens per second: 7382.47 | Training tokens per second (%): 11.41 | MFU (%): 13.83 | TFLOPs: 136.74
2025-05-18 16:15:52,110 - root - INFO - Step: 10 | Loss: 11.88 | Tokens per second: 7216.49 | Training tokens per second (%): 25.72 | MFU (%): 13.52 | TFLOPs: 133.67
2025-05-18 16:15:52,110 - root - INFO - Training completed
[W518 16:15:54.053890717 TCPStore.cpp:106] [c10d] sendBytes failed on SocketImpl(fd=3, addr=[nid006461]:55236, remote=[nid006461]:12355): Broken pipe
Exception raised from sendBytes at /opt/pytorch/pytorch/torch/csrc/distributed/c10d/Utils.hpp:646 (most recent call first):
frame #0: c10::Error::Error(c10::SourceLocation, std::__cxx11::basic_string<char, std::char_traits<char>, std::allocator<char> >) + 0xd4 (0x40005283bdd4 in /usr/local/lib/python3.12/dist-packages/torch/lib/libc10.so)
frame #1: <unknown function> + 0x58a89c0 (0x4000090989c0 in /usr/local/lib/python3.12/dist-packages/torch/lib/libtorch_cpu.so)
frame #2: <unknown function> + 0x58a8fcc (0x400009098fcc in /usr/local/lib/python3.12/dist-packages/torch/lib/libtorch_cpu.so)
frame #3: <unknown function> + 0x58ad124 (0x40000909d124 in /usr/local/lib/python3.12/dist-packages/torch/lib/libtorch_cpu.so)
frame #4: c10d::TCPStore::doWait(c10::ArrayRef<std::__cxx11::basic_string<char, std::char_traits<char>, std::allocator<char> > >, std::chrono::duration<long, std::ratio<1l, 1000l> >) + 0x148 (0x40000909ec48 in /usr/local/lib/python3.12/dist-packages/torch/lib/libtorch_cpu.so)
frame #5: c10d::TCPStore::doGet(std::__cxx11::basic_string<char, std::char_traits<char>, std::allocator<char> > const&) + 0x2c (0x40000909f10c in /usr/local/lib/python3.12/dist-packages/torch/lib/libtorch_cpu.so)
frame #6: c10d::TCPStore::get(std::__cxx11::basic_string<char, std::char_traits<char>, std::allocator<char> > const&) + 0x9c (0x4000090a061c in /usr/local/lib/python3.12/dist-packages/torch/lib/libtorch_cpu.so)
frame #7: <unknown function> + 0xfd9044 (0x4000036c9044 in /usr/local/lib/python3.12/dist-packages/torch/lib/libtorch_python.so)
frame #8: <unknown function> + 0x63c060 (0x400002d2c060 in /usr/local/lib/python3.12/dist-packages/torch/lib/libtorch_python.so)
frame #9: /usr/bin/python3() [0x503e14]
frame #10: _PyObject_MakeTpCall + 0x78 (0x4c2db8 in /usr/bin/python3)
frame #11: /usr/bin/python3() [0x4c709c]
frame #12: _PyEval_EvalFrameDefault + 0x3e70 (0x567d34 in /usr/bin/python3)
frame #13: _PyObject_Call_Prepend + 0xc4 (0x4c4894 in /usr/bin/python3)
frame #14: /usr/bin/python3() [0x529450]
frame #15: PyObject_Call + 0xa4 (0x4c52d4 in /usr/bin/python3)
frame #16: _PyEval_EvalFrameDefault + 0x3e70 (0x567d34 in /usr/bin/python3)
frame #17: PyEval_EvalCode + 0x130 (0x562ab4 in /usr/bin/python3)
frame #18: /usr/bin/python3() [0x55f968]
frame #19: /usr/bin/python3() [0x503c0c]
frame #20: PyObject_Vectorcall + 0x4c (0x4c396c in /usr/bin/python3)
frame #21: _PyEval_EvalFrameDefault + 0x8a0 (0x564764 in /usr/bin/python3)
frame #22: /usr/bin/python3() [0x68bad8]
frame #23: Py_RunMain + 0x1ac (0x68b19c in /usr/bin/python3)
frame #24: Py_BytesMain + 0x28 (0x68ae88 in /usr/bin/python3)
frame #25: <unknown function> + 0x284c4 (0x400001bc84c4 in /usr/lib/aarch64-linux-gnu/libc.so.6)
frame #26: __libc_start_main + 0x98 (0x400001bc8598 in /usr/lib/aarch64-linux-gnu/libc.so.6)
frame #27: _start + 0x30 (0x5f6e30 in /usr/bin/python3)

W0518 16:15:54.876000 150055 torch/distributed/elastic/rendezvous/dynamic_rendezvous.py:1284] The node 'nid006461_150055_0' has failed to shutdown the rendezvous 'none' due to an error of type RendezvousConnectionError.
[W518 16:15:54.066740418 TCPStore.cpp:106] [c10d] sendBytes failed on SocketImpl(fd=3, addr=[nid006461]:55236, remote=[nid006461]:12355): Broken pipe
Exception raised from sendBytes at /opt/pytorch/pytorch/torch/csrc/distributed/c10d/Utils.hpp:646 (most recent call first):
frame #0: c10::Error::Error(c10::SourceLocation, std::__cxx11::basic_string<char, std::char_traits<char>, std::allocator<char> >) + 0xd4 (0x40005283bdd4 in /usr/local/lib/python3.12/dist-packages/torch/lib/libc10.so)
frame #1: <unknown function> + 0x58a89c0 (0x4000090989c0 in /usr/local/lib/python3.12/dist-packages/torch/lib/libtorch_cpu.so)
frame #2: <unknown function> + 0x58a8fcc (0x400009098fcc in /usr/local/lib/python3.12/dist-packages/torch/lib/libtorch_cpu.so)
frame #3: <unknown function> + 0x58ad124 (0x40000909d124 in /usr/local/lib/python3.12/dist-packages/torch/lib/libtorch_cpu.so)
frame #4: c10d::TCPStore::doWait(c10::ArrayRef<std::__cxx11::basic_string<char, std::char_traits<char>, std::allocator<char> > >, std::chrono::duration<long, std::ratio<1l, 1000l> >) + 0x148 (0x40000909ec48 in /usr/local/lib/python3.12/dist-packages/torch/lib/libtorch_cpu.so)
frame #5: c10d::TCPStore::doGet(std::__cxx11::basic_string<char, std::char_traits<char>, std::allocator<char> > const&) + 0x2c (0x40000909f10c in /usr/local/lib/python3.12/dist-packages/torch/lib/libtorch_cpu.so)
frame #6: c10d::TCPStore::get(std::__cxx11::basic_string<char, std::char_traits<char>, std::allocator<char> > const&) + 0x9c (0x4000090a061c in /usr/local/lib/python3.12/dist-packages/torch/lib/libtorch_cpu.so)
frame #7: <unknown function> + 0xfd9044 (0x4000036c9044 in /usr/local/lib/python3.12/dist-packages/torch/lib/libtorch_python.so)
frame #8: <unknown function> + 0x63c060 (0x400002d2c060 in /usr/local/lib/python3.12/dist-packages/torch/lib/libtorch_python.so)
frame #9: /usr/bin/python3() [0x503e14]
frame #10: _PyObject_MakeTpCall + 0x78 (0x4c2db8 in /usr/bin/python3)
frame #11: /usr/bin/python3() [0x4c709c]
frame #12: _PyEval_EvalFrameDefault + 0x3e70 (0x567d34 in /usr/bin/python3)
frame #13: _PyObject_Call_Prepend + 0xc4 (0x4c4894 in /usr/bin/python3)
frame #14: /usr/bin/python3() [0x529450]
frame #15: PyObject_Call + 0xa4 (0x4c52d4 in /usr/bin/python3)
frame #16: _PyEval_EvalFrameDefault + 0x3e70 (0x567d34 in /usr/bin/python3)
frame #17: PyEval_EvalCode + 0x130 (0x562ab4 in /usr/bin/python3)
frame #18: /usr/bin/python3() [0x55f968]
frame #19: /usr/bin/python3() [0x503c0c]
frame #20: PyObject_Vectorcall + 0x4c (0x4c396c in /usr/bin/python3)
frame #21: _PyEval_EvalFrameDefault + 0x8a0 (0x564764 in /usr/bin/python3)
frame #22: /usr/bin/python3() [0x68bad8]
frame #23: Py_RunMain + 0x1ac (0x68b19c in /usr/bin/python3)
frame #24: Py_BytesMain + 0x28 (0x68ae88 in /usr/bin/python3)
frame #25: <unknown function> + 0x284c4 (0x400001bc84c4 in /usr/lib/aarch64-linux-gnu/libc.so.6)
frame #26: __libc_start_main + 0x98 (0x400001bc8598 in /usr/lib/aarch64-linux-gnu/libc.so.6)
frame #27: _start + 0x30 (0x5f6e30 in /usr/bin/python3)

W0518 16:15:54.888000 150055 torch/distributed/elastic/rendezvous/dynamic_rendezvous.py:1284] The node 'nid006461_150055_0' has failed to shutdown the rendezvous 'none' due to an error of type RendezvousConnectionError.
Traceback (most recent call last):
  File "/usr/local/lib/python3.12/dist-packages/torch/distributed/elastic/rendezvous/c10d_rendezvous_backend.py", line 117, in _call_store
    return getattr(self._store, store_op)(*args, **kwargs)
           ^^^^^^^^^^^^^^^^^^^^^^^^^^^^^^^^^^^^^^^^^^^^^^^
torch.distributed.DistNetworkError: failed to recv, got 0 bytes

The above exception was the direct cause of the following exception:

Traceback (most recent call last):
  File "<frozen runpy>", line 198, in _run_module_as_main
  File "<frozen runpy>", line 88, in _run_code
  File "/usr/local/lib/python3.12/dist-packages/torch/distributed/run.py", line 922, in <module>
    main()
  File "/usr/local/lib/python3.12/dist-packages/torch/distributed/elastic/multiprocessing/errors/__init__.py", line 355, in wrapper
    return f(*args, **kwargs)
           ^^^^^^^^^^^^^^^^^^
  File "/usr/local/lib/python3.12/dist-packages/torch/distributed/run.py", line 918, in main
    run(args)
  File "/usr/local/lib/python3.12/dist-packages/torch/distributed/run.py", line 909, in run
    elastic_launch(
  File "/usr/local/lib/python3.12/dist-packages/torch/distributed/launcher/api.py", line 138, in __call__
    return launch_agent(self._config, self._entrypoint, list(args))
           ^^^^^^^^^^^^^^^^^^^^^^^^^^^^^^^^^^^^^^^^^^^^^^^^^^^^^^^^
  File "/usr/local/lib/python3.12/dist-packages/torch/distributed/launcher/api.py", line 260, in launch_agent
    result = agent.run()
             ^^^^^^^^^^^
  File "/usr/local/lib/python3.12/dist-packages/torch/distributed/elastic/metrics/api.py", line 137, in wrapper
    result = f(*args, **kwargs)
             ^^^^^^^^^^^^^^^^^^
  File "/usr/local/lib/python3.12/dist-packages/torch/distributed/elastic/agent/server/api.py", line 711, in run
    result = self._invoke_run(role)
             ^^^^^^^^^^^^^^^^^^^^^^
  File "/usr/local/lib/python3.12/dist-packages/torch/distributed/elastic/agent/server/api.py", line 864, in _invoke_run
    self._initialize_workers(self._worker_group)
  File "/usr/local/lib/python3.12/dist-packages/torch/distributed/elastic/metrics/api.py", line 137, in wrapper
    result = f(*args, **kwargs)
             ^^^^^^^^^^^^^^^^^^
  File "/usr/local/lib/python3.12/dist-packages/torch/distributed/elastic/agent/server/api.py", line 683, in _initialize_workers
    self._rendezvous(worker_group)
  File "/usr/local/lib/python3.12/dist-packages/torch/distributed/elastic/metrics/api.py", line 137, in wrapper
    result = f(*args, **kwargs)
             ^^^^^^^^^^^^^^^^^^
  File "/usr/local/lib/python3.12/dist-packages/torch/distributed/elastic/agent/server/api.py", line 500, in _rendezvous
    rdzv_info = spec.rdzv_handler.next_rendezvous()
                ^^^^^^^^^^^^^^^^^^^^^^^^^^^^^^^^^^^
  File "/usr/local/lib/python3.12/dist-packages/torch/distributed/elastic/rendezvous/dynamic_rendezvous.py", line 1162, in next_rendezvous
    self._op_executor.run(join_op, deadline, self._get_deadline)
  File "/usr/local/lib/python3.12/dist-packages/torch/distributed/elastic/rendezvous/dynamic_rendezvous.py", line 648, in run
    has_set = self._state_holder.sync()
              ^^^^^^^^^^^^^^^^^^^^^^^^^
  File "/usr/local/lib/python3.12/dist-packages/torch/distributed/elastic/rendezvous/dynamic_rendezvous.py", line 437, in sync
    get_response = self._backend.get_state()
                   ^^^^^^^^^^^^^^^^^^^^^^^^^
  File "/usr/local/lib/python3.12/dist-packages/torch/distributed/elastic/rendezvous/c10d_rendezvous_backend.py", line 75, in get_state
    base64_state: bytes = self._call_store("get", self._key)
                          ^^^^^^^^^^^^^^^^^^^^^^^^^^^^^^^^^^
  File "/usr/local/lib/python3.12/dist-packages/torch/distributed/elastic/rendezvous/c10d_rendezvous_backend.py", line 119, in _call_store
    raise RendezvousConnectionError(
torch.distributed.elastic.rendezvous.api.RendezvousConnectionError: The connection to the C10d store has failed. See inner exception for details.
[W518 16:15:54.126206131 TCPStore.cpp:106] [c10d] sendBytes failed on SocketImpl(fd=3, addr=[nid006461]:55206, remote=[nid006461]:12355): Broken pipe
Exception raised from sendBytes at /opt/pytorch/pytorch/torch/csrc/distributed/c10d/Utils.hpp:646 (most recent call first):
frame #0: c10::Error::Error(c10::SourceLocation, std::__cxx11::basic_string<char, std::char_traits<char>, std::allocator<char> >) + 0xd4 (0x40007133bdd4 in /usr/local/lib/python3.12/dist-packages/torch/lib/libc10.so)
frame #1: <unknown function> + 0x58a89c0 (0x400027b989c0 in /usr/local/lib/python3.12/dist-packages/torch/lib/libtorch_cpu.so)
frame #2: <unknown function> + 0x58a8fcc (0x400027b98fcc in /usr/local/lib/python3.12/dist-packages/torch/lib/libtorch_cpu.so)
frame #3: <unknown function> + 0x58ad124 (0x400027b9d124 in /usr/local/lib/python3.12/dist-packages/torch/lib/libtorch_cpu.so)
frame #4: c10d::TCPStore::doWait(c10::ArrayRef<std::__cxx11::basic_string<char, std::char_traits<char>, std::allocator<char> > >, std::chrono::duration<long, std::ratio<1l, 1000l> >) + 0x148 (0x400027b9ec48 in /usr/local/lib/python3.12/dist-packages/torch/lib/libtorch_cpu.so)
frame #5: c10d::TCPStore::doGet(std::__cxx11::basic_string<char, std::char_traits<char>, std::allocator<char> > const&) + 0x2c (0x400027b9f10c in /usr/local/lib/python3.12/dist-packages/torch/lib/libtorch_cpu.so)
frame #6: c10d::TCPStore::get(std::__cxx11::basic_string<char, std::char_traits<char>, std::allocator<char> > const&) + 0x9c (0x400027ba061c in /usr/local/lib/python3.12/dist-packages/torch/lib/libtorch_cpu.so)
frame #7: <unknown function> + 0xfd9044 (0x4000221c9044 in /usr/local/lib/python3.12/dist-packages/torch/lib/libtorch_python.so)
frame #8: <unknown function> + 0x63c060 (0x40002182c060 in /usr/local/lib/python3.12/dist-packages/torch/lib/libtorch_python.so)
frame #9: /usr/bin/python3() [0x503e14]
frame #10: _PyObject_MakeTpCall + 0x78 (0x4c2db8 in /usr/bin/python3)
frame #11: /usr/bin/python3() [0x4c709c]
frame #12: _PyEval_EvalFrameDefault + 0x3e70 (0x567d34 in /usr/bin/python3)
frame #13: _PyObject_Call_Prepend + 0xc4 (0x4c4894 in /usr/bin/python3)
frame #14: /usr/bin/python3() [0x529450]
frame #15: PyObject_Call + 0xa4 (0x4c52d4 in /usr/bin/python3)
frame #16: _PyEval_EvalFrameDefault + 0x3e70 (0x567d34 in /usr/bin/python3)
frame #17: PyEval_EvalCode + 0x130 (0x562ab4 in /usr/bin/python3)
frame #18: /usr/bin/python3() [0x55f968]
frame #19: /usr/bin/python3() [0x503c0c]
frame #20: PyObject_Vectorcall + 0x4c (0x4c396c in /usr/bin/python3)
frame #21: _PyEval_EvalFrameDefault + 0x8a0 (0x564764 in /usr/bin/python3)
frame #22: /usr/bin/python3() [0x68bad8]
frame #23: Py_RunMain + 0x1ac (0x68b19c in /usr/bin/python3)
frame #24: Py_BytesMain + 0x28 (0x68ae88 in /usr/bin/python3)
frame #25: <unknown function> + 0x284c4 (0x4000206c84c4 in /usr/lib/aarch64-linux-gnu/libc.so.6)
frame #26: __libc_start_main + 0x98 (0x4000206c8598 in /usr/lib/aarch64-linux-gnu/libc.so.6)
frame #27: _start + 0x30 (0x5f6e30 in /usr/bin/python3)

W0518 16:15:54.948000 150054 torch/distributed/elastic/rendezvous/dynamic_rendezvous.py:1284] The node 'nid006461_150054_0' has failed to shutdown the rendezvous 'none' due to an error of type RendezvousConnectionError.
[W518 16:15:54.137532680 TCPStore.cpp:106] [c10d] sendBytes failed on SocketImpl(fd=3, addr=[nid006461]:55206, remote=[nid006461]:12355): Broken pipe
Exception raised from sendBytes at /opt/pytorch/pytorch/torch/csrc/distributed/c10d/Utils.hpp:646 (most recent call first):
frame #0: c10::Error::Error(c10::SourceLocation, std::__cxx11::basic_string<char, std::char_traits<char>, std::allocator<char> >) + 0xd4 (0x40007133bdd4 in /usr/local/lib/python3.12/dist-packages/torch/lib/libc10.so)
frame #1: <unknown function> + 0x58a89c0 (0x400027b989c0 in /usr/local/lib/python3.12/dist-packages/torch/lib/libtorch_cpu.so)
frame #2: <unknown function> + 0x58a8fcc (0x400027b98fcc in /usr/local/lib/python3.12/dist-packages/torch/lib/libtorch_cpu.so)
frame #3: <unknown function> + 0x58ad124 (0x400027b9d124 in /usr/local/lib/python3.12/dist-packages/torch/lib/libtorch_cpu.so)
frame #4: c10d::TCPStore::doWait(c10::ArrayRef<std::__cxx11::basic_string<char, std::char_traits<char>, std::allocator<char> > >, std::chrono::duration<long, std::ratio<1l, 1000l> >) + 0x148 (0x400027b9ec48 in /usr/local/lib/python3.12/dist-packages/torch/lib/libtorch_cpu.so)
frame #5: c10d::TCPStore::doGet(std::__cxx11::basic_string<char, std::char_traits<char>, std::allocator<char> > const&) + 0x2c (0x400027b9f10c in /usr/local/lib/python3.12/dist-packages/torch/lib/libtorch_cpu.so)
frame #6: c10d::TCPStore::get(std::__cxx11::basic_string<char, std::char_traits<char>, std::allocator<char> > const&) + 0x9c (0x400027ba061c in /usr/local/lib/python3.12/dist-packages/torch/lib/libtorch_cpu.so)
frame #7: <unknown function> + 0xfd9044 (0x4000221c9044 in /usr/local/lib/python3.12/dist-packages/torch/lib/libtorch_python.so)
frame #8: <unknown function> + 0x63c060 (0x40002182c060 in /usr/local/lib/python3.12/dist-packages/torch/lib/libtorch_python.so)
frame #9: /usr/bin/python3() [0x503e14]
frame #10: _PyObject_MakeTpCall + 0x78 (0x4c2db8 in /usr/bin/python3)
frame #11: /usr/bin/python3() [0x4c709c]
frame #12: _PyEval_EvalFrameDefault + 0x3e70 (0x567d34 in /usr/bin/python3)
frame #13: _PyObject_Call_Prepend + 0xc4 (0x4c4894 in /usr/bin/python3)
frame #14: /usr/bin/python3() [0x529450]
frame #15: PyObject_Call + 0xa4 (0x4c52d4 in /usr/bin/python3)
frame #16: _PyEval_EvalFrameDefault + 0x3e70 (0x567d34 in /usr/bin/python3)
frame #17: PyEval_EvalCode + 0x130 (0x562ab4 in /usr/bin/python3)
frame #18: /usr/bin/python3() [0x55f968]
frame #19: /usr/bin/python3() [0x503c0c]
frame #20: PyObject_Vectorcall + 0x4c (0x4c396c in /usr/bin/python3)
frame #21: _PyEval_EvalFrameDefault + 0x8a0 (0x564764 in /usr/bin/python3)
frame #22: /usr/bin/python3() [0x68bad8]
frame #23: Py_RunMain + 0x1ac (0x68b19c in /usr/bin/python3)
frame #24: Py_BytesMain + 0x28 (0x68ae88 in /usr/bin/python3)
frame #25: <unknown function> + 0x284c4 (0x4000206c84c4 in /usr/lib/aarch64-linux-gnu/libc.so.6)
frame #26: __libc_start_main + 0x98 (0x4000206c8598 in /usr/lib/aarch64-linux-gnu/libc.so.6)
frame #27: _start + 0x30 (0x5f6e30 in /usr/bin/python3)

W0518 16:15:54.959000 150054 torch/distributed/elastic/rendezvous/dynamic_rendezvous.py:1284] The node 'nid006461_150054_0' has failed to shutdown the rendezvous 'none' due to an error of type RendezvousConnectionError.
Traceback (most recent call last):
  File "/usr/local/lib/python3.12/dist-packages/torch/distributed/elastic/rendezvous/c10d_rendezvous_backend.py", line 117, in _call_store
    return getattr(self._store, store_op)(*args, **kwargs)
           ^^^^^^^^^^^^^^^^^^^^^^^^^^^^^^^^^^^^^^^^^^^^^^^
torch.distributed.DistNetworkError: failed to recv, got 0 bytes

The above exception was the direct cause of the following exception:

Traceback (most recent call last):
  File "<frozen runpy>", line 198, in _run_module_as_main
  File "<frozen runpy>", line 88, in _run_code
  File "/usr/local/lib/python3.12/dist-packages/torch/distributed/run.py", line 922, in <module>
    main()
  File "/usr/local/lib/python3.12/dist-packages/torch/distributed/elastic/multiprocessing/errors/__init__.py", line 355, in wrapper
    return f(*args, **kwargs)
           ^^^^^^^^^^^^^^^^^^
  File "/usr/local/lib/python3.12/dist-packages/torch/distributed/run.py", line 918, in main
    run(args)
  File "/usr/local/lib/python3.12/dist-packages/torch/distributed/run.py", line 909, in run
    elastic_launch(
  File "/usr/local/lib/python3.12/dist-packages/torch/distributed/launcher/api.py", line 138, in __call__
    return launch_agent(self._config, self._entrypoint, list(args))
           ^^^^^^^^^^^^^^^^^^^^^^^^^^^^^^^^^^^^^^^^^^^^^^^^^^^^^^^^
  File "/usr/local/lib/python3.12/dist-packages/torch/distributed/launcher/api.py", line 260, in launch_agent
    result = agent.run()
             ^^^^^^^^^^^
  File "/usr/local/lib/python3.12/dist-packages/torch/distributed/elastic/metrics/api.py", line 137, in wrapper
    result = f(*args, **kwargs)
             ^^^^^^^^^^^^^^^^^^
  File "/usr/local/lib/python3.12/dist-packages/torch/distributed/elastic/agent/server/api.py", line 711, in run
    result = self._invoke_run(role)
             ^^^^^^^^^^^^^^^^^^^^^^
  File "/usr/local/lib/python3.12/dist-packages/torch/distributed/elastic/agent/server/api.py", line 864, in _invoke_run
    self._initialize_workers(self._worker_group)
  File "/usr/local/lib/python3.12/dist-packages/torch/distributed/elastic/metrics/api.py", line 137, in wrapper
    result = f(*args, **kwargs)
             ^^^^^^^^^^^^^^^^^^
  File "/usr/local/lib/python3.12/dist-packages/torch/distributed/elastic/agent/server/api.py", line 683, in _initialize_workers
    self._rendezvous(worker_group)
  File "/usr/local/lib/python3.12/dist-packages/torch/distributed/elastic/metrics/api.py", line 137, in wrapper
    result = f(*args, **kwargs)
             ^^^^^^^^^^^^^^^^^^
  File "/usr/local/lib/python3.12/dist-packages/torch/distributed/elastic/agent/server/api.py", line 500, in _rendezvous
    rdzv_info = spec.rdzv_handler.next_rendezvous()
                ^^^^^^^^^^^^^^^^^^^^^^^^^^^^^^^^^^^
  File "/usr/local/lib/python3.12/dist-packages/torch/distributed/elastic/rendezvous/dynamic_rendezvous.py", line 1162, in next_rendezvous
    self._op_executor.run(join_op, deadline, self._get_deadline)
  File "/usr/local/lib/python3.12/dist-packages/torch/distributed/elastic/rendezvous/dynamic_rendezvous.py", line 648, in run
    has_set = self._state_holder.sync()
              ^^^^^^^^^^^^^^^^^^^^^^^^^
  File "/usr/local/lib/python3.12/dist-packages/torch/distributed/elastic/rendezvous/dynamic_rendezvous.py", line 437, in sync
    get_response = self._backend.get_state()
                   ^^^^^^^^^^^^^^^^^^^^^^^^^
  File "/usr/local/lib/python3.12/dist-packages/torch/distributed/elastic/rendezvous/c10d_rendezvous_backend.py", line 75, in get_state
    base64_state: bytes = self._call_store("get", self._key)
                          ^^^^^^^^^^^^^^^^^^^^^^^^^^^^^^^^^^
  File "/usr/local/lib/python3.12/dist-packages/torch/distributed/elastic/rendezvous/c10d_rendezvous_backend.py", line 119, in _call_store
    raise RendezvousConnectionError(
torch.distributed.elastic.rendezvous.api.RendezvousConnectionError: The connection to the C10d store has failed. See inner exception for details.
srun: error: nid006461: task 3: Exited with exit code 1
srun: Terminating StepId=447086.0
slurmstepd: error: *** STEP 447086.0 ON nid006461 CANCELLED AT 2025-05-18T16:15:55 ***
srun: error: nid006461: tasks 1-2: Terminated
srun: Force Terminated StepId=447086.0
END TIME: Sun May 18 16:15:56 CEST 2025
