START TIME: Sun May 18 13:35:44 CEST 2025
slurmstepd: error: couldn't chdir to `/workspace': No such file or directory: going to /tmp instead
slurmstepd: error: couldn't chdir to `/workspace': No such file or directory: going to /tmp instead
slurmstepd: error: couldn't chdir to `/workspace': No such file or directory: going to /tmp instead
slurmstepd: error: couldn't chdir to `/workspace': No such file or directory: going to /tmp instead
slurmstepd: error: couldn't chdir to `/workspace': No such file or directory: going to /tmp instead
slurmstepd: error: couldn't chdir to `/workspace': No such file or directory: going to /tmp instead
slurmstepd: error: couldn't chdir to `/workspace': No such file or directory: going to /tmp instead
slurmstepd: error: couldn't chdir to `/workspace': No such file or directory: going to /tmp instead
usage: train_fsdp.py [-h] [--dataset DATASET]
                     [--tokenizer-name-or-path TOKENIZER_NAME_OR_PATH]
                     [--sequence-length SEQUENCE_LENGTH]
                     [--batch-size BATCH_SIZE] [--fused-optimizer]
                     [--learning-rate LEARNING_RATE]
                     [--lr-warmup-steps LR_WARMUP_STEPS]
                     [--training-steps TRAINING_STEPS]
                     [--logging-frequency LOGGING_FREQUENCY] [--profile]
                     [--profile-step-start PROFILE_STEP_START]
                     [--profile-step-end PROFILE_STEP_END]
                     [--grad-max-norm GRAD_MAX_NORM]
                     [--model-dtype MODEL_DTYPE] [--compile]
train_fsdp.py: error: unrecognized arguments: --scale 27 --seed 42
E0518 13:36:06.862000 34294 torch/distributed/elastic/multiprocessing/api.py:869] failed (exitcode: 2) local_rank: 0 (pid: 34652) of binary: /usr/bin/python3
Traceback (most recent call last):
  File "<frozen runpy>", line 198, in _run_module_as_main
  File "<frozen runpy>", line 88, in _run_code
  File "/usr/local/lib/python3.12/dist-packages/torch/distributed/run.py", line 922, in <module>
    main()
  File "/usr/local/lib/python3.12/dist-packages/torch/distributed/elastic/multiprocessing/errors/__init__.py", line 355, in wrapper
    return f(*args, **kwargs)
           ^^^^^^^^^^^^^^^^^^
  File "/usr/local/lib/python3.12/dist-packages/torch/distributed/run.py", line 918, in main
    run(args)
  File "/usr/local/lib/python3.12/dist-packages/torch/distributed/run.py", line 909, in run
    elastic_launch(
  File "/usr/local/lib/python3.12/dist-packages/torch/distributed/launcher/api.py", line 138, in __call__
    return launch_agent(self._config, self._entrypoint, list(args))
           ^^^^^^^^^^^^^^^^^^^^^^^^^^^^^^^^^^^^^^^^^^^^^^^^^^^^^^^^
  File "/usr/local/lib/python3.12/dist-packages/torch/distributed/launcher/api.py", line 269, in launch_agent
    raise ChildFailedError(
torch.distributed.elastic.multiprocessing.errors.ChildFailedError: 
============================================================
/iopsstor/scratch/cscs/elyulina/lai-proj/train_fsdp.py FAILED
------------------------------------------------------------
Failures:
  <NO_OTHER_FAILURES>
------------------------------------------------------------
Root Cause (first observed failure):
[0]:
  time      : 2025-05-18_13:36:06
  host      : nid006443
  rank      : 0 (local_rank: 0)
  exitcode  : 2 (pid: 34652)
  error_file: <N/A>
  traceback : To enable traceback see: https://pytorch.org/docs/stable/elastic/errors.html
============================================================
[W518 13:36:07.094104726 TCPStore.cpp:106] [c10d] sendBytes failed on SocketImpl(fd=3, addr=[nid006446-hsn2]:57512, remote=[nid006443]:12355): Broken pipe
Exception raised from sendBytes at /opt/pytorch/pytorch/torch/csrc/distributed/c10d/Utils.hpp:646 (most recent call first):
frame #0: c10::Error::Error(c10::SourceLocation, std::__cxx11::basic_string<char, std::char_traits<char>, std::allocator<char> >) + 0xd4 (0x40009099bdd4 in /usr/local/lib/python3.12/dist-packages/torch/lib/libc10.so)
frame #1: <unknown function> + 0x58a89c0 (0x4000471f89c0 in /usr/local/lib/python3.12/dist-packages/torch/lib/libtorch_cpu.so)
frame #2: <unknown function> + 0x58a8fcc (0x4000471f8fcc in /usr/local/lib/python3.12/dist-packages/torch/lib/libtorch_cpu.so)
frame #3: <unknown function> + 0x58ad124 (0x4000471fd124 in /usr/local/lib/python3.12/dist-packages/torch/lib/libtorch_cpu.so)
frame #4: c10d::TCPStore::doWait(c10::ArrayRef<std::__cxx11::basic_string<char, std::char_traits<char>, std::allocator<char> > >, std::chrono::duration<long, std::ratio<1l, 1000l> >) + 0x148 (0x4000471fec48 in /usr/local/lib/python3.12/dist-packages/torch/lib/libtorch_cpu.so)
frame #5: c10d::TCPStore::doGet(std::__cxx11::basic_string<char, std::char_traits<char>, std::allocator<char> > const&) + 0x2c (0x4000471ff10c in /usr/local/lib/python3.12/dist-packages/torch/lib/libtorch_cpu.so)
frame #6: c10d::TCPStore::get(std::__cxx11::basic_string<char, std::char_traits<char>, std::allocator<char> > const&) + 0x9c (0x40004720061c in /usr/local/lib/python3.12/dist-packages/torch/lib/libtorch_cpu.so)
frame #7: <unknown function> + 0xfd9044 (0x400041829044 in /usr/local/lib/python3.12/dist-packages/torch/lib/libtorch_python.so)
frame #8: <unknown function> + 0x63c060 (0x400040e8c060 in /usr/local/lib/python3.12/dist-packages/torch/lib/libtorch_python.so)
frame #9: /usr/bin/python3() [0x503e14]
frame #10: _PyObject_MakeTpCall + 0x78 (0x4c2db8 in /usr/bin/python3)
frame #11: /usr/bin/python3() [0x4c709c]
frame #12: _PyEval_EvalFrameDefault + 0x3e70 (0x567d34 in /usr/bin/python3)
frame #13: _PyObject_Call_Prepend + 0xc4 (0x4c4894 in /usr/bin/python3)
frame #14: /usr/bin/python3() [0x529450]
frame #15: PyObject_Call + 0xa4 (0x4c52d4 in /usr/bin/python3)
frame #16: _PyEval_EvalFrameDefault + 0x3e70 (0x567d34 in /usr/bin/python3)
frame #17: PyEval_EvalCode + 0x130 (0x562ab4 in /usr/bin/python3)
frame #18: /usr/bin/python3() [0x55f968]
frame #19: /usr/bin/python3() [0x503c0c]
frame #20: PyObject_Vectorcall + 0x4c (0x4c396c in /usr/bin/python3)
frame #21: _PyEval_EvalFrameDefault + 0x8a0 (0x564764 in /usr/bin/python3)
frame #22: /usr/bin/python3() [0x68bad8]
frame #23: Py_RunMain + 0x1ac (0x68b19c in /usr/bin/python3)
frame #24: Py_BytesMain + 0x28 (0x68ae88 in /usr/bin/python3)
frame #25: <unknown function> + 0x284c4 (0x40003fd284c4 in /usr/lib/aarch64-linux-gnu/libc.so.6)
frame #26: __libc_start_main + 0x98 (0x40003fd28598 in /usr/lib/aarch64-linux-gnu/libc.so.6)
frame #27: _start + 0x30 (0x5f6e30 in /usr/bin/python3)

W0518 13:36:07.181000 59408 torch/distributed/elastic/rendezvous/dynamic_rendezvous.py:1284] The node 'nid006446_59408_0' has failed to shutdown the rendezvous 'none' due to an error of type RendezvousConnectionError.
[W518 13:36:07.108260573 TCPStore.cpp:106] [c10d] sendBytes failed on SocketImpl(fd=3, addr=[nid006446-hsn2]:57512, remote=[nid006443]:12355): Broken pipe
Exception raised from sendBytes at /opt/pytorch/pytorch/torch/csrc/distributed/c10d/Utils.hpp:646 (most recent call first):
frame #0: c10::Error::Error(c10::SourceLocation, std::__cxx11::basic_string<char, std::char_traits<char>, std::allocator<char> >) + 0xd4 (0x40009099bdd4 in /usr/local/lib/python3.12/dist-packages/torch/lib/libc10.so)
frame #1: <unknown function> + 0x58a89c0 (0x4000471f89c0 in /usr/local/lib/python3.12/dist-packages/torch/lib/libtorch_cpu.so)
frame #2: <unknown function> + 0x58a8fcc (0x4000471f8fcc in /usr/local/lib/python3.12/dist-packages/torch/lib/libtorch_cpu.so)
frame #3: <unknown function> + 0x58ad124 (0x4000471fd124 in /usr/local/lib/python3.12/dist-packages/torch/lib/libtorch_cpu.so)
frame #4: c10d::TCPStore::doWait(c10::ArrayRef<std::__cxx11::basic_string<char, std::char_traits<char>, std::allocator<char> > >, std::chrono::duration<long, std::ratio<1l, 1000l> >) + 0x148 (0x4000471fec48 in /usr/local/lib/python3.12/dist-packages/torch/lib/libtorch_cpu.so)
frame #5: c10d::TCPStore::doGet(std::__cxx11::basic_string<char, std::char_traits<char>, std::allocator<char> > const&) + 0x2c (0x4000471ff10c in /usr/local/lib/python3.12/dist-packages/torch/lib/libtorch_cpu.so)
frame #6: c10d::TCPStore::get(std::__cxx11::basic_string<char, std::char_traits<char>, std::allocator<char> > const&) + 0x9c (0x40004720061c in /usr/local/lib/python3.12/dist-packages/torch/lib/libtorch_cpu.so)
frame #7: <unknown function> + 0xfd9044 (0x400041829044 in /usr/local/lib/python3.12/dist-packages/torch/lib/libtorch_python.so)
frame #8: <unknown function> + 0x63c060 (0x400040e8c060 in /usr/local/lib/python3.12/dist-packages/torch/lib/libtorch_python.so)
frame #9: /usr/bin/python3() [0x503e14]
frame #10: _PyObject_MakeTpCall + 0x78 (0x4c2db8 in /usr/bin/python3)
frame #11: /usr/bin/python3() [0x4c709c]
frame #12: _PyEval_EvalFrameDefault + 0x3e70 (0x567d34 in /usr/bin/python3)
frame #13: _PyObject_Call_Prepend + 0xc4 (0x4c4894 in /usr/bin/python3)
frame #14: /usr/bin/python3() [0x529450]
frame #15: PyObject_Call + 0xa4 (0x4c52d4 in /usr/bin/python3)
frame #16: _PyEval_EvalFrameDefault + 0x3e70 (0x567d34 in /usr/bin/python3)
frame #17: PyEval_EvalCode + 0x130 (0x562ab4 in /usr/bin/python3)
frame #18: /usr/bin/python3() [0x55f968]
frame #19: /usr/bin/python3() [0x503c0c]
frame #20: PyObject_Vectorcall + 0x4c (0x4c396c in /usr/bin/python3)
frame #21: _PyEval_EvalFrameDefault + 0x8a0 (0x564764 in /usr/bin/python3)
frame #22: /usr/bin/python3() [0x68bad8]
frame #23: Py_RunMain + 0x1ac (0x68b19c in /usr/bin/python3)
frame #24: Py_BytesMain + 0x28 (0x68ae88 in /usr/bin/python3)
frame #25: <unknown function> + 0x284c4 (0x40003fd284c4 in /usr/lib/aarch64-linux-gnu/libc.so.6)
frame #26: __libc_start_main + 0x98 (0x40003fd28598 in /usr/lib/aarch64-linux-gnu/libc.so.6)
frame #27: _start + 0x30 (0x5f6e30 in /usr/bin/python3)

W0518 13:36:07.195000 59408 torch/distributed/elastic/rendezvous/dynamic_rendezvous.py:1284] The node 'nid006446_59408_0' has failed to shutdown the rendezvous 'none' due to an error of type RendezvousConnectionError.
Traceback (most recent call last):
  File "/usr/local/lib/python3.12/dist-packages/torch/distributed/elastic/rendezvous/c10d_rendezvous_backend.py", line 117, in _call_store
    return getattr(self._store, store_op)(*args, **kwargs)
           ^^^^^^^^^^^^^^^^^^^^^^^^^^^^^^^^^^^^^^^^^^^^^^^
torch.distributed.DistNetworkError: failed to recv, got 0 bytes

The above exception was the direct cause of the following exception:

Traceback (most recent call last):
  File "<frozen runpy>", line 198, in _run_module_as_main
  File "<frozen runpy>", line 88, in _run_code
  File "/usr/local/lib/python3.12/dist-packages/torch/distributed/run.py", line 922, in <module>
    main()
  File "/usr/local/lib/python3.12/dist-packages/torch/distributed/elastic/multiprocessing/errors/__init__.py", line 355, in wrapper
    return f(*args, **kwargs)
           ^^^^^^^^^^^^^^^^^^
  File "/usr/local/lib/python3.12/dist-packages/torch/distributed/run.py", line 918, in main
    run(args)
  File "/usr/local/lib/python3.12/dist-packages/torch/distributed/run.py", line 909, in run
    elastic_launch(
  File "/usr/local/lib/python3.12/dist-packages/torch/distributed/launcher/api.py", line 138, in __call__
    return launch_agent(self._config, self._entrypoint, list(args))
           ^^^^^^^^^^^^^^^^^^^^^^^^^^^^^^^^^^^^^^^^^^^^^^^^^^^^^^^^
  File "/usr/local/lib/python3.12/dist-packages/torch/distributed/launcher/api.py", line 260, in launch_agent
    result = agent.run()
             ^^^^^^^^^^^
  File "/usr/local/lib/python3.12/dist-packages/torch/distributed/elastic/metrics/api.py", line 137, in wrapper
    result = f(*args, **kwargs)
             ^^^^^^^^^^^^^^^^^^
  File "/usr/local/lib/python3.12/dist-packages/torch/distributed/elastic/agent/server/api.py", line 711, in run
    result = self._invoke_run(role)
             ^^^^^^^^^^^^^^^^^^^^^^
  File "/usr/local/lib/python3.12/dist-packages/torch/distributed/elastic/agent/server/api.py", line 864, in _invoke_run
    self._initialize_workers(self._worker_group)
  File "/usr/local/lib/python3.12/dist-packages/torch/distributed/elastic/metrics/api.py", line 137, in wrapper
    result = f(*args, **kwargs)
             ^^^^^^^^^^^^^^^^^^
  File "/usr/local/lib/python3.12/dist-packages/torch/distributed/elastic/agent/server/api.py", line 683, in _initialize_workers
    self._rendezvous(worker_group)
  File "/usr/local/lib/python3.12/dist-packages/torch/distributed/elastic/metrics/api.py", line 137, in wrapper
    result = f(*args, **kwargs)
             ^^^^^^^^^^^^^^^^^^
  File "/usr/local/lib/python3.12/dist-packages/torch/distributed/elastic/agent/server/api.py", line 500, in _rendezvous
    rdzv_info = spec.rdzv_handler.next_rendezvous()
                ^^^^^^^^^^^^^^^^^^^^^^^^^^^^^^^^^^^
  File "/usr/local/lib/python3.12/dist-packages/torch/distributed/elastic/rendezvous/dynamic_rendezvous.py", line 1162, in next_rendezvous
    self._op_executor.run(join_op, deadline, self._get_deadline)
  File "/usr/local/lib/python3.12/dist-packages/torch/distributed/elastic/rendezvous/dynamic_rendezvous.py", line 648, in run
    has_set = self._state_holder.sync()
              ^^^^^^^^^^^^^^^^^^^^^^^^^
  File "/usr/local/lib/python3.12/dist-packages/torch/distributed/elastic/rendezvous/dynamic_rendezvous.py", line 437, in sync
    get_response = self._backend.get_state()
                   ^^^^^^^^^^^^^^^^^^^^^^^^^
  File "/usr/local/lib/python3.12/dist-packages/torch/distributed/elastic/rendezvous/c10d_rendezvous_backend.py", line 75, in get_state
    base64_state: bytes = self._call_store("get", self._key)
                          ^^^^^^^^^^^^^^^^^^^^^^^^^^^^^^^^^^
  File "/usr/local/lib/python3.12/dist-packages/torch/distributed/elastic/rendezvous/c10d_rendezvous_backend.py", line 119, in _call_store
    raise RendezvousConnectionError(
torch.distributed.elastic.rendezvous.api.RendezvousConnectionError: The connection to the C10d store has failed. See inner exception for details.
[W518 13:36:07.217748049 TCPStore.cpp:106] [c10d] sendBytes failed on SocketImpl(fd=3, addr=[nid006445-hsn3]:56872, remote=[nid006443]:12355): Broken pipe
Exception raised from sendBytes at /opt/pytorch/pytorch/torch/csrc/distributed/c10d/Utils.hpp:646 (most recent call first):
frame #0: c10::Error::Error(c10::SourceLocation, std::__cxx11::basic_string<char, std::char_traits<char>, std::allocator<char> >) + 0xd4 (0x400065b0bdd4 in /usr/local/lib/python3.12/dist-packages/torch/lib/libc10.so)
frame #1: <unknown function> + 0x58a89c0 (0x40001c3689c0 in /usr/local/lib/python3.12/dist-packages/torch/lib/libtorch_cpu.so)
frame #2: <unknown function> + 0x58a8fcc (0x40001c368fcc in /usr/local/lib/python3.12/dist-packages/torch/lib/libtorch_cpu.so)
frame #3: <unknown function> + 0x58ad124 (0x40001c36d124 in /usr/local/lib/python3.12/dist-packages/torch/lib/libtorch_cpu.so)
frame #4: c10d::TCPStore::doWait(c10::ArrayRef<std::__cxx11::basic_string<char, std::char_traits<char>, std::allocator<char> > >, std::chrono::duration<long, std::ratio<1l, 1000l> >) + 0x148 (0x40001c36ec48 in /usr/local/lib/python3.12/dist-packages/torch/lib/libtorch_cpu.so)
frame #5: c10d::TCPStore::doGet(std::__cxx11::basic_string<char, std::char_traits<char>, std::allocator<char> > const&) + 0x2c (0x40001c36f10c in /usr/local/lib/python3.12/dist-packages/torch/lib/libtorch_cpu.so)
frame #6: c10d::TCPStore::get(std::__cxx11::basic_string<char, std::char_traits<char>, std::allocator<char> > const&) + 0x9c (0x40001c37061c in /usr/local/lib/python3.12/dist-packages/torch/lib/libtorch_cpu.so)
frame #7: <unknown function> + 0xfd9044 (0x400016999044 in /usr/local/lib/python3.12/dist-packages/torch/lib/libtorch_python.so)
frame #8: <unknown function> + 0x63c060 (0x400015ffc060 in /usr/local/lib/python3.12/dist-packages/torch/lib/libtorch_python.so)
frame #9: /usr/bin/python3() [0x503e14]
frame #10: _PyObject_MakeTpCall + 0x78 (0x4c2db8 in /usr/bin/python3)
frame #11: /usr/bin/python3() [0x4c709c]
frame #12: _PyEval_EvalFrameDefault + 0x3e70 (0x567d34 in /usr/bin/python3)
frame #13: _PyObject_Call_Prepend + 0xc4 (0x4c4894 in /usr/bin/python3)
frame #14: /usr/bin/python3() [0x529450]
frame #15: PyObject_Call + 0xa4 (0x4c52d4 in /usr/bin/python3)
frame #16: _PyEval_EvalFrameDefault + 0x3e70 (0x567d34 in /usr/bin/python3)
frame #17: PyEval_EvalCode + 0x130 (0x562ab4 in /usr/bin/python3)
frame #18: /usr/bin/python3() [0x55f968]
frame #19: /usr/bin/python3() [0x503c0c]
frame #20: PyObject_Vectorcall + 0x4c (0x4c396c in /usr/bin/python3)
frame #21: _PyEval_EvalFrameDefault + 0x8a0 (0x564764 in /usr/bin/python3)
frame #22: /usr/bin/python3() [0x68bad8]
frame #23: Py_RunMain + 0x1ac (0x68b19c in /usr/bin/python3)
frame #24: Py_BytesMain + 0x28 (0x68ae88 in /usr/bin/python3)
frame #25: <unknown function> + 0x284c4 (0x400014e984c4 in /usr/lib/aarch64-linux-gnu/libc.so.6)
frame #26: __libc_start_main + 0x98 (0x400014e98598 in /usr/lib/aarch64-linux-gnu/libc.so.6)
frame #27: _start + 0x30 (0x5f6e30 in /usr/bin/python3)

W0518 13:36:07.461000 144513 torch/distributed/elastic/rendezvous/dynamic_rendezvous.py:1284] The node 'nid006445_144513_0' has failed to shutdown the rendezvous 'none' due to an error of type RendezvousConnectionError.
[W518 13:36:07.230091079 TCPStore.cpp:106] [c10d] sendBytes failed on SocketImpl(fd=3, addr=[nid006445-hsn3]:56872, remote=[nid006443]:12355): Broken pipe
Exception raised from sendBytes at /opt/pytorch/pytorch/torch/csrc/distributed/c10d/Utils.hpp:646 (most recent call first):
frame #0: c10::Error::Error(c10::SourceLocation, std::__cxx11::basic_string<char, std::char_traits<char>, std::allocator<char> >) + 0xd4 (0x400065b0bdd4 in /usr/local/lib/python3.12/dist-packages/torch/lib/libc10.so)
frame #1: <unknown function> + 0x58a89c0 (0x40001c3689c0 in /usr/local/lib/python3.12/dist-packages/torch/lib/libtorch_cpu.so)
frame #2: <unknown function> + 0x58a8fcc (0x40001c368fcc in /usr/local/lib/python3.12/dist-packages/torch/lib/libtorch_cpu.so)
frame #3: <unknown function> + 0x58ad124 (0x40001c36d124 in /usr/local/lib/python3.12/dist-packages/torch/lib/libtorch_cpu.so)
frame #4: c10d::TCPStore::doWait(c10::ArrayRef<std::__cxx11::basic_string<char, std::char_traits<char>, std::allocator<char> > >, std::chrono::duration<long, std::ratio<1l, 1000l> >) + 0x148 (0x40001c36ec48 in /usr/local/lib/python3.12/dist-packages/torch/lib/libtorch_cpu.so)
frame #5: c10d::TCPStore::doGet(std::__cxx11::basic_string<char, std::char_traits<char>, std::allocator<char> > const&) + 0x2c (0x40001c36f10c in /usr/local/lib/python3.12/dist-packages/torch/lib/libtorch_cpu.so)
frame #6: c10d::TCPStore::get(std::__cxx11::basic_string<char, std::char_traits<char>, std::allocator<char> > const&) + 0x9c (0x40001c37061c in /usr/local/lib/python3.12/dist-packages/torch/lib/libtorch_cpu.so)
frame #7: <unknown function> + 0xfd9044 (0x400016999044 in /usr/local/lib/python3.12/dist-packages/torch/lib/libtorch_python.so)
frame #8: <unknown function> + 0x63c060 (0x400015ffc060 in /usr/local/lib/python3.12/dist-packages/torch/lib/libtorch_python.so)
frame #9: /usr/bin/python3() [0x503e14]
frame #10: _PyObject_MakeTpCall + 0x78 (0x4c2db8 in /usr/bin/python3)
frame #11: /usr/bin/python3() [0x4c709c]
frame #12: _PyEval_EvalFrameDefault + 0x3e70 (0x567d34 in /usr/bin/python3)
frame #13: _PyObject_Call_Prepend + 0xc4 (0x4c4894 in /usr/bin/python3)
frame #14: /usr/bin/python3() [0x529450]
frame #15: PyObject_Call + 0xa4 (0x4c52d4 in /usr/bin/python3)
frame #16: _PyEval_EvalFrameDefault + 0x3e70 (0x567d34 in /usr/bin/python3)
frame #17: PyEval_EvalCode + 0x130 (0x562ab4 in /usr/bin/python3)
frame #18: /usr/bin/python3() [0x55f968]
frame #19: /usr/bin/python3() [0x503c0c]
frame #20: PyObject_Vectorcall + 0x4c (0x4c396c in /usr/bin/python3)
frame #21: _PyEval_EvalFrameDefault + 0x8a0 (0x564764 in /usr/bin/python3)
frame #22: /usr/bin/python3() [0x68bad8]
frame #23: Py_RunMain + 0x1ac (0x68b19c in /usr/bin/python3)
frame #24: Py_BytesMain + 0x28 (0x68ae88 in /usr/bin/python3)
frame #25: <unknown function> + 0x284c4 (0x400014e984c4 in /usr/lib/aarch64-linux-gnu/libc.so.6)
frame #26: __libc_start_main + 0x98 (0x400014e98598 in /usr/lib/aarch64-linux-gnu/libc.so.6)
frame #27: _start + 0x30 (0x5f6e30 in /usr/bin/python3)

W0518 13:36:07.473000 144513 torch/distributed/elastic/rendezvous/dynamic_rendezvous.py:1284] The node 'nid006445_144513_0' has failed to shutdown the rendezvous 'none' due to an error of type RendezvousConnectionError.
Traceback (most recent call last):
  File "/usr/local/lib/python3.12/dist-packages/torch/distributed/elastic/rendezvous/c10d_rendezvous_backend.py", line 117, in _call_store
    return getattr(self._store, store_op)(*args, **kwargs)
           ^^^^^^^^^^^^^^^^^^^^^^^^^^^^^^^^^^^^^^^^^^^^^^^
torch.distributed.DistNetworkError: failed to recv, got 0 bytes

The above exception was the direct cause of the following exception:

Traceback (most recent call last):
  File "<frozen runpy>", line 198, in _run_module_as_main
  File "<frozen runpy>", line 88, in _run_code
  File "/usr/local/lib/python3.12/dist-packages/torch/distributed/run.py", line 922, in <module>
    main()
  File "/usr/local/lib/python3.12/dist-packages/torch/distributed/elastic/multiprocessing/errors/__init__.py", line 355, in wrapper
    return f(*args, **kwargs)
           ^^^^^^^^^^^^^^^^^^
  File "/usr/local/lib/python3.12/dist-packages/torch/distributed/run.py", line 918, in main
    run(args)
  File "/usr/local/lib/python3.12/dist-packages/torch/distributed/run.py", line 909, in run
    elastic_launch(
  File "/usr/local/lib/python3.12/dist-packages/torch/distributed/launcher/api.py", line 138, in __call__
    return launch_agent(self._config, self._entrypoint, list(args))
           ^^^^^^^^^^^^^^^^^^^^^^^^^^^^^^^^^^^^^^^^^^^^^^^^^^^^^^^^
  File "/usr/local/lib/python3.12/dist-packages/torch/distributed/launcher/api.py", line 260, in launch_agent
    result = agent.run()
             ^^^^^^^^^^^
  File "/usr/local/lib/python3.12/dist-packages/torch/distributed/elastic/metrics/api.py", line 137, in wrapper
    result = f(*args, **kwargs)
             ^^^^^^^^^^^^^^^^^^
  File "/usr/local/lib/python3.12/dist-packages/torch/distributed/elastic/agent/server/api.py", line 711, in run
    result = self._invoke_run(role)
             ^^^^^^^^^^^^^^^^^^^^^^
  File "/usr/local/lib/python3.12/dist-packages/torch/distributed/elastic/agent/server/api.py", line 864, in _invoke_run
    self._initialize_workers(self._worker_group)
  File "/usr/local/lib/python3.12/dist-packages/torch/distributed/elastic/metrics/api.py", line 137, in wrapper
    result = f(*args, **kwargs)
             ^^^^^^^^^^^^^^^^^^
  File "/usr/local/lib/python3.12/dist-packages/torch/distributed/elastic/agent/server/api.py", line 683, in _initialize_workers
    self._rendezvous(worker_group)
  File "/usr/local/lib/python3.12/dist-packages/torch/distributed/elastic/metrics/api.py", line 137, in wrapper
    result = f(*args, **kwargs)
             ^^^^^^^^^^^^^^^^^^
  File "/usr/local/lib/python3.12/dist-packages/torch/distributed/elastic/agent/server/api.py", line 500, in _rendezvous
    rdzv_info = spec.rdzv_handler.next_rendezvous()
                ^^^^^^^^^^^^^^^^^^^^^^^^^^^^^^^^^^^
  File "/usr/local/lib/python3.12/dist-packages/torch/distributed/elastic/rendezvous/dynamic_rendezvous.py", line 1162, in next_rendezvous
    self._op_executor.run(join_op, deadline, self._get_deadline)
  File "/usr/local/lib/python3.12/dist-packages/torch/distributed/elastic/rendezvous/dynamic_rendezvous.py", line 648, in run
    has_set = self._state_holder.sync()
              ^^^^^^^^^^^^^^^^^^^^^^^^^
  File "/usr/local/lib/python3.12/dist-packages/torch/distributed/elastic/rendezvous/dynamic_rendezvous.py", line 437, in sync
    get_response = self._backend.get_state()
                   ^^^^^^^^^^^^^^^^^^^^^^^^^
  File "/usr/local/lib/python3.12/dist-packages/torch/distributed/elastic/rendezvous/c10d_rendezvous_backend.py", line 75, in get_state
    base64_state: bytes = self._call_store("get", self._key)
                          ^^^^^^^^^^^^^^^^^^^^^^^^^^^^^^^^^^
  File "/usr/local/lib/python3.12/dist-packages/torch/distributed/elastic/rendezvous/c10d_rendezvous_backend.py", line 119, in _call_store
    raise RendezvousConnectionError(
torch.distributed.elastic.rendezvous.api.RendezvousConnectionError: The connection to the C10d store has failed. See inner exception for details.
[W518 13:36:07.645271420 TCPStore.cpp:106] [c10d] sendBytes failed on SocketImpl(fd=3, addr=[nid006444-hsn1]:56576, remote=[nid006443]:12355): Broken pipe
Exception raised from sendBytes at /opt/pytorch/pytorch/torch/csrc/distributed/c10d/Utils.hpp:646 (most recent call first):
frame #0: c10::Error::Error(c10::SourceLocation, std::__cxx11::basic_string<char, std::char_traits<char>, std::allocator<char> >) + 0xd4 (0x40006ba3bdd4 in /usr/local/lib/python3.12/dist-packages/torch/lib/libc10.so)
frame #1: <unknown function> + 0x58a89c0 (0x4000222989c0 in /usr/local/lib/python3.12/dist-packages/torch/lib/libtorch_cpu.so)
frame #2: <unknown function> + 0x58a8fcc (0x400022298fcc in /usr/local/lib/python3.12/dist-packages/torch/lib/libtorch_cpu.so)
frame #3: <unknown function> + 0x58ad124 (0x40002229d124 in /usr/local/lib/python3.12/dist-packages/torch/lib/libtorch_cpu.so)
frame #4: c10d::TCPStore::doWait(c10::ArrayRef<std::__cxx11::basic_string<char, std::char_traits<char>, std::allocator<char> > >, std::chrono::duration<long, std::ratio<1l, 1000l> >) + 0x148 (0x40002229ec48 in /usr/local/lib/python3.12/dist-packages/torch/lib/libtorch_cpu.so)
frame #5: c10d::TCPStore::doGet(std::__cxx11::basic_string<char, std::char_traits<char>, std::allocator<char> > const&) + 0x2c (0x40002229f10c in /usr/local/lib/python3.12/dist-packages/torch/lib/libtorch_cpu.so)
frame #6: c10d::TCPStore::get(std::__cxx11::basic_string<char, std::char_traits<char>, std::allocator<char> > const&) + 0x9c (0x4000222a061c in /usr/local/lib/python3.12/dist-packages/torch/lib/libtorch_cpu.so)
frame #7: <unknown function> + 0xfd9044 (0x40001c8c9044 in /usr/local/lib/python3.12/dist-packages/torch/lib/libtorch_python.so)
frame #8: <unknown function> + 0x63c060 (0x40001bf2c060 in /usr/local/lib/python3.12/dist-packages/torch/lib/libtorch_python.so)
frame #9: /usr/bin/python3() [0x503e14]
frame #10: _PyObject_MakeTpCall + 0x78 (0x4c2db8 in /usr/bin/python3)
frame #11: /usr/bin/python3() [0x4c709c]
frame #12: _PyEval_EvalFrameDefault + 0x3e70 (0x567d34 in /usr/bin/python3)
frame #13: _PyObject_Call_Prepend + 0xc4 (0x4c4894 in /usr/bin/python3)
frame #14: /usr/bin/python3() [0x529450]
frame #15: PyObject_Call + 0xa4 (0x4c52d4 in /usr/bin/python3)
frame #16: _PyEval_EvalFrameDefault + 0x3e70 (0x567d34 in /usr/bin/python3)
frame #17: PyEval_EvalCode + 0x130 (0x562ab4 in /usr/bin/python3)
frame #18: /usr/bin/python3() [0x55f968]
frame #19: /usr/bin/python3() [0x503c0c]
frame #20: PyObject_Vectorcall + 0x4c (0x4c396c in /usr/bin/python3)
frame #21: _PyEval_EvalFrameDefault + 0x8a0 (0x564764 in /usr/bin/python3)
frame #22: /usr/bin/python3() [0x68bad8]
frame #23: Py_RunMain + 0x1ac (0x68b19c in /usr/bin/python3)
frame #24: Py_BytesMain + 0x28 (0x68ae88 in /usr/bin/python3)
frame #25: <unknown function> + 0x284c4 (0x40001adc84c4 in /usr/lib/aarch64-linux-gnu/libc.so.6)
frame #26: __libc_start_main + 0x98 (0x40001adc8598 in /usr/lib/aarch64-linux-gnu/libc.so.6)
frame #27: _start + 0x30 (0x5f6e30 in /usr/bin/python3)

W0518 13:36:07.567000 102061 torch/distributed/elastic/rendezvous/dynamic_rendezvous.py:1284] The node 'nid006444_102061_0' has failed to shutdown the rendezvous 'none' due to an error of type RendezvousConnectionError.
[W518 13:36:07.658206880 TCPStore.cpp:106] [c10d] sendBytes failed on SocketImpl(fd=3, addr=[nid006444-hsn1]:56576, remote=[nid006443]:12355): Broken pipe
Exception raised from sendBytes at /opt/pytorch/pytorch/torch/csrc/distributed/c10d/Utils.hpp:646 (most recent call first):
frame #0: c10::Error::Error(c10::SourceLocation, std::__cxx11::basic_string<char, std::char_traits<char>, std::allocator<char> >) + 0xd4 (0x40006ba3bdd4 in /usr/local/lib/python3.12/dist-packages/torch/lib/libc10.so)
frame #1: <unknown function> + 0x58a89c0 (0x4000222989c0 in /usr/local/lib/python3.12/dist-packages/torch/lib/libtorch_cpu.so)
frame #2: <unknown function> + 0x58a8fcc (0x400022298fcc in /usr/local/lib/python3.12/dist-packages/torch/lib/libtorch_cpu.so)
frame #3: <unknown function> + 0x58ad124 (0x40002229d124 in /usr/local/lib/python3.12/dist-packages/torch/lib/libtorch_cpu.so)
frame #4: c10d::TCPStore::doWait(c10::ArrayRef<std::__cxx11::basic_string<char, std::char_traits<char>, std::allocator<char> > >, std::chrono::duration<long, std::ratio<1l, 1000l> >) + 0x148 (0x40002229ec48 in /usr/local/lib/python3.12/dist-packages/torch/lib/libtorch_cpu.so)
frame #5: c10d::TCPStore::doGet(std::__cxx11::basic_string<char, std::char_traits<char>, std::allocator<char> > const&) + 0x2c (0x40002229f10c in /usr/local/lib/python3.12/dist-packages/torch/lib/libtorch_cpu.so)
frame #6: c10d::TCPStore::get(std::__cxx11::basic_string<char, std::char_traits<char>, std::allocator<char> > const&) + 0x9c (0x4000222a061c in /usr/local/lib/python3.12/dist-packages/torch/lib/libtorch_cpu.so)
frame #7: <unknown function> + 0xfd9044 (0x40001c8c9044 in /usr/local/lib/python3.12/dist-packages/torch/lib/libtorch_python.so)
frame #8: <unknown function> + 0x63c060 (0x40001bf2c060 in /usr/local/lib/python3.12/dist-packages/torch/lib/libtorch_python.so)
frame #9: /usr/bin/python3() [0x503e14]
frame #10: _PyObject_MakeTpCall + 0x78 (0x4c2db8 in /usr/bin/python3)
frame #11: /usr/bin/python3() [0x4c709c]
frame #12: _PyEval_EvalFrameDefault + 0x3e70 (0x567d34 in /usr/bin/python3)
frame #13: _PyObject_Call_Prepend + 0xc4 (0x4c4894 in /usr/bin/python3)
frame #14: /usr/bin/python3() [0x529450]
frame #15: PyObject_Call + 0xa4 (0x4c52d4 in /usr/bin/python3)
frame #16: _PyEval_EvalFrameDefault + 0x3e70 (0x567d34 in /usr/bin/python3)
frame #17: PyEval_EvalCode + 0x130 (0x562ab4 in /usr/bin/python3)
frame #18: /usr/bin/python3() [0x55f968]
frame #19: /usr/bin/python3() [0x503c0c]
frame #20: PyObject_Vectorcall + 0x4c (0x4c396c in /usr/bin/python3)
frame #21: _PyEval_EvalFrameDefault + 0x8a0 (0x564764 in /usr/bin/python3)
frame #22: /usr/bin/python3() [0x68bad8]
frame #23: Py_RunMain + 0x1ac (0x68b19c in /usr/bin/python3)
frame #24: Py_BytesMain + 0x28 (0x68ae88 in /usr/bin/python3)
frame #25: <unknown function> + 0x284c4 (0x40001adc84c4 in /usr/lib/aarch64-linux-gnu/libc.so.6)
frame #26: __libc_start_main + 0x98 (0x40001adc8598 in /usr/lib/aarch64-linux-gnu/libc.so.6)
frame #27: _start + 0x30 (0x5f6e30 in /usr/bin/python3)

W0518 13:36:07.579000 102061 torch/distributed/elastic/rendezvous/dynamic_rendezvous.py:1284] The node 'nid006444_102061_0' has failed to shutdown the rendezvous 'none' due to an error of type RendezvousConnectionError.
Traceback (most recent call last):
  File "/usr/local/lib/python3.12/dist-packages/torch/distributed/elastic/rendezvous/c10d_rendezvous_backend.py", line 117, in _call_store
    return getattr(self._store, store_op)(*args, **kwargs)
           ^^^^^^^^^^^^^^^^^^^^^^^^^^^^^^^^^^^^^^^^^^^^^^^
torch.distributed.DistNetworkError: failed to recv, got 0 bytes

The above exception was the direct cause of the following exception:

Traceback (most recent call last):
  File "<frozen runpy>", line 198, in _run_module_as_main
  File "<frozen runpy>", line 88, in _run_code
  File "/usr/local/lib/python3.12/dist-packages/torch/distributed/run.py", line 922, in <module>
    main()
  File "/usr/local/lib/python3.12/dist-packages/torch/distributed/elastic/multiprocessing/errors/__init__.py", line 355, in wrapper
    return f(*args, **kwargs)
           ^^^^^^^^^^^^^^^^^^
  File "/usr/local/lib/python3.12/dist-packages/torch/distributed/run.py", line 918, in main
    run(args)
  File "/usr/local/lib/python3.12/dist-packages/torch/distributed/run.py", line 909, in run
    elastic_launch(
  File "/usr/local/lib/python3.12/dist-packages/torch/distributed/launcher/api.py", line 138, in __call__
    return launch_agent(self._config, self._entrypoint, list(args))
           ^^^^^^^^^^^^^^^^^^^^^^^^^^^^^^^^^^^^^^^^^^^^^^^^^^^^^^^^
  File "/usr/local/lib/python3.12/dist-packages/torch/distributed/launcher/api.py", line 260, in launch_agent
    result = agent.run()
             ^^^^^^^^^^^
  File "/usr/local/lib/python3.12/dist-packages/torch/distributed/elastic/metrics/api.py", line 137, in wrapper
    result = f(*args, **kwargs)
             ^^^^^^^^^^^^^^^^^^
  File "/usr/local/lib/python3.12/dist-packages/torch/distributed/elastic/agent/server/api.py", line 711, in run
    result = self._invoke_run(role)
             ^^^^^^^^^^^^^^^^^^^^^^
  File "/usr/local/lib/python3.12/dist-packages/torch/distributed/elastic/agent/server/api.py", line 864, in _invoke_run
    self._initialize_workers(self._worker_group)
  File "/usr/local/lib/python3.12/dist-packages/torch/distributed/elastic/metrics/api.py", line 137, in wrapper
    result = f(*args, **kwargs)
             ^^^^^^^^^^^^^^^^^^
  File "/usr/local/lib/python3.12/dist-packages/torch/distributed/elastic/agent/server/api.py", line 683, in _initialize_workers
    self._rendezvous(worker_group)
  File "/usr/local/lib/python3.12/dist-packages/torch/distributed/elastic/metrics/api.py", line 137, in wrapper
    result = f(*args, **kwargs)
             ^^^^^^^^^^^^^^^^^^
  File "/usr/local/lib/python3.12/dist-packages/torch/distributed/elastic/agent/server/api.py", line 500, in _rendezvous
    rdzv_info = spec.rdzv_handler.next_rendezvous()
                ^^^^^^^^^^^^^^^^^^^^^^^^^^^^^^^^^^^
  File "/usr/local/lib/python3.12/dist-packages/torch/distributed/elastic/rendezvous/dynamic_rendezvous.py", line 1162, in next_rendezvous
    self._op_executor.run(join_op, deadline, self._get_deadline)
  File "/usr/local/lib/python3.12/dist-packages/torch/distributed/elastic/rendezvous/dynamic_rendezvous.py", line 648, in run
    has_set = self._state_holder.sync()
              ^^^^^^^^^^^^^^^^^^^^^^^^^
  File "/usr/local/lib/python3.12/dist-packages/torch/distributed/elastic/rendezvous/dynamic_rendezvous.py", line 437, in sync
    get_response = self._backend.get_state()
                   ^^^^^^^^^^^^^^^^^^^^^^^^^
  File "/usr/local/lib/python3.12/dist-packages/torch/distributed/elastic/rendezvous/c10d_rendezvous_backend.py", line 75, in get_state
    base64_state: bytes = self._call_store("get", self._key)
                          ^^^^^^^^^^^^^^^^^^^^^^^^^^^^^^^^^^
  File "/usr/local/lib/python3.12/dist-packages/torch/distributed/elastic/rendezvous/c10d_rendezvous_backend.py", line 119, in _call_store
    raise RendezvousConnectionError(
torch.distributed.elastic.rendezvous.api.RendezvousConnectionError: The connection to the C10d store has failed. See inner exception for details.
srun: error: nid006443: task 0: Exited with exit code 1
srun: Terminating StepId=446773.0
srun: error: nid006446: task 3: Exited with exit code 1
srun: error: nid006445: task 2: Exited with exit code 1
srun: error: nid006444: task 1: Exited with exit code 1
END TIME: Sun May 18 13:36:08 CEST 2025
